Workbook

Sheet 需求
A3: 完成进度 | E3: 跳转链接
A4: 已完成 | B4: 01 | C4: 新装备 | D4: 新装备类型：熔炼装备 分基础属性和熔炼属性，基础属性永远不变，熔炼属性可强化和替换。 鉴定前可以装备但是仅有基础属性 熔炼装备不可进行镶嵌 唤灵 启灵 融合 精铸。 熔炼装备部位和普通装备一致，装在普通装备的装备栏。 未绑定的装备穿戴时，弹出提示框："穿戴后装备将与角色绑定，无法被其他角色穿戴" 绑定后，装备描述中添加一行 "[角色名]专属" 熔炼装备都在三圣山-装备背包里 | I4: 1.穿戴后锁定角色 给装备加上角色名 专属：xxx 穿戴时候提示 该装备穿戴后将成为穿戴角色的专属装备 其他角色将无法穿戴。 避免玩家 将同职业已强化好的装备给小号穿 2.强化等级继承后原装备 标记为不可继承 加输入框来提示 同一件装备仅可继承一次强化等级或印记 避免玩家通过继承 强化一件装备 多个角色使用该强化等级 3.熔炼后 不要摧毁 有其他职业属性 4.分解给熔炼石 10换1未鉴定的 熔炼装备 可指定部位 5.带强化等级和印记的装备不可分解
A5: 已完成 | B5: 02 | C5: 新功能 | D5: 装备熔炼界面，勾选词条进行替换 | E5: =HYPERLINK("#案子!B107","熔炼界面案子") -> 熔炼界面案子 | I5: 6.强化熔炼装备所提升的数值 在容量装备tips描述上下面单写一下 增加强化带来的提升展现力
A6: 已完成 | B6: 03 | C6: 掉落产出 | D6: 熔炼词条生成与显示规则： | E6: =HYPERLINK("#案子!G32","产出规则") -> 产出规则 | I6: 7.熔炼属性只可替换 不可新增 如果目标装备属性为0 则不可替换新属性上去
A7: 已完成 | B7: 04 | C7: 属性池 | D7: 装备属性池配置 | E7: =HYPERLINK("#熔炼属性池!A33","熔炼属性池表") -> 熔炼属性池表
A8: 已完成 | B8: 05 | C8: 分解 | D8: 熔炼装备分解配置在三圣山分解功能里，分解后获得[熔炼石] 带有强化等级/印记的装备不能被分解 | F8: 改名 原因 对应的系统 产出对应关联的名称 起名规则 第一需求 是功能性 见名知意 第二再考虑加修饰词
A9: 已完成 | B9: 06 | C9: 分解后循环 | D9: 装备分解的材料可以兑换指定部位装备，放在第一章的npc(神秘人) 给熔炼石上加上兑换引导说明
A10: 已完成 | B10: 07 | C10: 强化 | D10: 强化走原有的银子强化 首次强化一件未强化的熔炼装备，弹出提示框："强化后此装备不可作为熔炼素材装备" 强化属性单独显示在熔炼属性下方，单开一条【强化属性】 属性显示没有词条颜色区分，显示加成"[职业]属性名 +数值（+百分比）" 如果本身就是百分比属性，则显示"[职业]属性名 +百分比" | F10: 这个限制用不到了
A11: 已完成 | B11: 08 | C11: 掉落产出 | D11: 第一章的关卡开炼狱模式，分别掉落不同部位的装备 怪物掉落的装备都是鉴定前道具 | E11: =HYPERLINK("#案子!G9","掉落产出表") -> 掉落产出表 | I11: 数值模拟结果如何
A12: 已完成 | B12: 09 | C12: 特殊消耗品 | D12: 添加各部位鉴定前道具，使用直接生成装备，使用消耗银子，使用成功前弹提示框（后期可能会消耗金子，预留） 放在三圣山背包里 | I12: 尽量用老的强化提升比例带入
A13: 已完成 | B13: 10 | C13: 数值规划 | D13: 首套装备满强化后数值达到目前最高属性的50% | E13: =HYPERLINK("#装备属性池!A33","属性数值表") -> 属性数值表
D16: .
A18: 类型 | B18: 道具名 | C18: 品质 | D18: 产出 | E18: 描述
A19: 三圣山-材料 | B19: 熔炼石 | C19: 紫色 | D19: 分解获得，每次分解获得1个 | E19: 熔炼之物消散时聚成的碎片，可以在NPC[唐周]处兑换好物。
A20: 三圣山-消耗品 | B20: 黄巾将军-熔炼装备自选箱 | C20: 绿色 | D20: 熔炼石*10兑换 | E20: 被炼狱的业火熔炼而成的神秘装备宝匣
A21: 三圣山-消耗品 | B21: 人公将军-张梁的防具宝匣 | C21: 紫色 | D21: 副本内掉落 | E21: 被炼狱的业火熔炼而成的神秘装备宝匣
A22: 三圣山-消耗品 | B22: 地公将军-张宝的首饰宝匣 | C22: 紫色
A23: 三圣山-消耗品 | B23: 天公将军-张角的武器宝匣 | C23: 紫色
A24: 防具 | B24: 人公将军·头盔 | C24: 橙色 | F24: 装备等级55
A25: 防具 | B25: 人公将军·衣服 | C25: 橙色
A26: 防具 | B26: 人公将军·腰带 | C26: 橙色
A27: 防具 | B27: 人公将军·鞋子 | C27: 橙色
A28: 防具 | B28: 人公将军·裤子 | C28: 橙色
A29: 首饰 | B29: 地公将军·项链 | C29: 橙色
A30: 首饰 | B30: 地公将军·手镯 | C30: 橙色
A31: 首饰 | B31: 地公将军·戒指 | C31: 橙色
A32: 武器-水晶剑 | B32: 天公将军·水晶剑 | C32: 橙色
A33: 武器-长剑 | B33: 天公将军·长剑 | C33: 橙色
A34: 武器-刀 | B34: 天公将军·刀 | C34: 橙色
A35: 武器-大剑 | B35: 天公将军·大剑 | C35: 橙色
A36: 武器-拳套 | B36: 天公将军·拳套 | C36: 橙色
... A47: 武器-镰刀 | B47: 天公将军·镰刀 | C47: 橙色
B50: 道具名 | C50: 品质 | D50: 价格 | E50: 描述
B51: 业火碎片 | C51: 蓝色 | D51: 分解获得，每次分解获得5个 | E51: 熔炼之物消散时聚成的碎片，将其与熔炼锤融合，或许能使熔炼锤有更强的作用。
B52: 熔炼锤 | C52: 蓝色 | E52: 不知何人打造的锤子，似乎能破除炼狱业火... 在熔炼鉴定处使用
B53: 中级熔炼锤-青龙 | C53: 紫色 | D53: 熔炼鉴定石+30熔炼碎片 | E53: 不知何人打造的锤子，似乎能破除炼狱业火... 在熔炼鉴定处使用
B54: 中级熔炼锤-白虎 | C54: 紫色 | D54: 熔炼鉴定石+30熔炼碎片 | E54: 不知何人打造的锤子，似乎能破除炼狱业火... 在熔炼鉴定处使用
B55: 中级熔炼锤-朱雀 | C55: 紫色 | D55: 熔炼鉴定石+30熔炼碎片 | E55: 不知何人打造的锤子，似乎能破除炼狱业火... 在熔炼鉴定处使用
B56: 中级熔炼锤-玄武 | C56: 紫色 | D56: 熔炼鉴定石+30熔炼碎片 | E56: 不知何人打造的锤子，似乎能破除炼狱业火... 在熔炼鉴定处使用
B57: 高级熔炼锤-青龙 | C57: 绿色 | D57: 熔炼鉴定石+60熔炼碎片 | E57: 不知何人打造的锤子，似乎能破除炼狱业火... 在熔炼鉴定处使用
...

Sheet 案子
F1: 玩法逻辑
B2: 玩法逻辑
F9: 掉落产出
B11: 装备熔炼 | G11: 产出途径 | H11: 掉落道具 | J11: 打开可随机获得 | K11: 限制 | M11: 利剑 | N11: 巨刃 | O11: 阔刀 | P11: 晶锋 | S11: 词条随机概率可调整
B12: 目的：给新人玩家一个可成长的装备 | G12: 曲阳之战-炼狱-张梁 | H12: 人公将军-张梁的防具宝匣 | I12: 头盔 | J12: ="人公将军·"&I12 -> 人公将军·头盔 | K12: 通用 | M12: 拳套 | N12: 指环 | O12: 利爪 | P12: 拳刃 | S12: 基础属性随着新装备推出提升
B13: 曲阳之战开启炼狱模式 | I13: 衣服 | J13: ="人公将军·"&I13 -> 人公将军·衣服 | M13: 飞针 | N13: 玉翎 | O13: 火器 | P13: 玫瑰 | S13: 新装备会提升熔炼属性的增长系数
B14: 难度低 | I14: 腰带 | J14: ="人公将军·"&I14 -> 人公将军·腰带 | M14: 法杖 | N14: 长柄 | O14: 手杖 | P14: 镰刀 | S14: 不同套装间根据套装特殊效果做区分
B15: 熔炼装备不可进行镶嵌 唤灵 启灵 融合、精铸。 | I15: 鞋子 | J15: ="人公将军·"&I15 -> 人公将军·鞋子
B16: 强化等级和印记可继承 | I16: 裤子 | J16: ="人公将军·"&I16 -> 人公将军·裤子
G17: 广宗之战-炼狱-张宝 | H17: 地公将军-张宝的首饰宝匣 | I17: 项链 | J17: ="地公将军·"&I17 -> 地公将军·项链 | L17: 产出计算：
B18: 装备放在三圣山背包里 | I18: 手镯 | J18: ="地公将军·"&I18 -> 地公将军·手镯 | L18: 体力消耗 | M18: 地图数量 | N18: 角色体力 | O18: 数值区间 | P18: 装备数量 | Q18: 职业 | R18: 产量/天 | S18: 毕业需求量 | T18: 毕业时间/天 | U18: 消耗银子 | V18: 90000
B19: 强化走原有的银子强化功能 | I19: 戒指 | J19: ="地公将军·"&I19 -> 地公将军·戒指 | L19: 4 | M19: 5 | N19: 180 | O19: 0.01 | P19: 9 | Q19: 16 | R19: =N19/(L19*M19)*Q19 -> 144 | S19: =P19*16/O19 -> 14400 | T19: =S19/R19 -> 100 | U19: =S19*V$18 -> 1296000000
B20: 熔炼装备可以激活所有的 甲专精 | G20: 邺城守卫战-炼狱-张角 | H20: 天公将军-张角的武器宝匣 | I20: 水晶剑 | J20: ="天公将军·"&I20 -> 天公将军·水晶剑 | K20: 职业限定 | L20: 4 | M20: 5 | N20: 180 | O20: 0.05 | P20: 9 | Q20: 16 | R20: =N20/(L20*M20)*Q20 -> 144 | S20: =P20*16/O20 -> 2880 | T20: =S20/R20 -> 20 | U20: =S20*V$18 -> 259200000
I21: 长剑 | J21: ="天公将军·"&I21 -> 天公将军·长剑 | L21: 4 | M21: 5 | N21: 180 | O21: 0.1 | P21: 9 | Q21: 16 | R21: =N21/(L21*M21)*Q21 -> 144 | S21: =P21*16/O21 -> 1440 | T21: =S21/R21 -> 10 | U21: =S21*V$18 -> 129600000
I22: 刀 | J22: ="天公将军·"&I22 -> 天公将军·刀 | L22: 4 | M22: 5 | N22: 180 | O22: 0.15 | P22: 9 | Q22: 16 | R22: =N22/(L22*M22)*Q22 -> 144 | S22: =P22*16/O22 -> 960 | T22: =S22/R22 -> 6.6666667 | U22: =S22*V$18 -> 86400000
B23: 属性随机 | C23: 开放熔炼相关功能 | I23: 大剑 | J23: ="天公将军·"&I23 -> 天公将军·大剑 | L23: 4 | M23: 5 | N23: 180 | O23: 0.2 | P23: 9 | Q23: 16 | R23: =N23/(L23*M23)*Q23 -> 144 | S23: =P23*16/O23 -> 720 | T23: =S23/R23 -> 5 | U23: =S23*V$18 -> 64800000
I24: 拳套 | J24: ="天公将军·"&I24 -> 天公将军·拳套 | L24: 4 | M24: 5 | N24: 180 | O24: 0.3 | P24: 9 | Q24: 16 | R24: =N24/(L24*M24)*Q24 -> 144 | S24: =P24*16/O24 -> 480 | T24: =S24/R24 -> 3.3333333 | U24: =S24*V$18 -> 43200000
I25: 指环 | J25: ="天公将军·"&I25 -> 天公将军·指环 | L25: 4 | M25: 5 | N25: 180 | O25: 0.4 | P25: 9 | Q25: 16 | R25: =N25/(L25*M25)*Q25 -> 144 | S25: =P25*16/O25 -> 360 | T25: =S25/R25 -> 2.5 | U25: =S25*V$18 -> 32400000
I26: 爪 | J26: ="天公将军·"&I26 -> 天公将军·爪 | L26: 4 | M26: 5 | N26: 180 | O26: 0.5 | P26: 9 | Q26: 16 | R26: =N26/(L26*M26)*Q26 -> 144 | S26: =P26*16/O26 -> 288 | T26: =S26/R26 -> 2 | U26: =S26*V$18 -> 25920000
B27: 以后再出 地公装备 天公装备 属性可以均可以进行转移 | I27: 巨拳 | J27: ="天公将军·"&I27 -> 天公将军·巨拳
I28: 飞针 | J28: ="天公将军·"&I28 -> 天公将军·飞针
I29: 翎 | J29: ="天公将军·"&I29 -> 天公将军·翎
I30: 玫瑰 | J30: ="天公将军·"&I30 -> 天公将军·玫瑰
I31: 火器 | J31: ="天公将军·"&I31 -> 天公将军·火器
I32: 手杖 | J32: ="天公将军·"&I32 -> 天公将军·手杖
I33: 长柄 | J33: ="天公将军·"&I33 -> 天公将军·长柄
I34: 法杖 | J34: ="天公将军·"&I34 -> 天公将军·法杖
I35: 镰刀 | J35: ="天公将军·"&I35 -> 天公将军·镰刀
F42: 生成规则
B43: 显示规则
B44: 【熔炼属性】 | C44: 可用职业 | D44: 属性词条 | E44: 词条数值
B45: 【强化属性】 | C45: 可用职业 | D45: 属性词条 | E45: 词条数值（加成比例）
B46: 生成规则
B47: 1.可用职业和词条数值为随机生成
B48: 2.可用职业会影响词条数值最终收益
B49: 3.可用职业和随机结果值分别随机
B50: 4.随机结果值经过属性转化比例得出最终数值
B51: 5.可用职业影响属性转化比例
B52: 养成玩法
B53: 熔炼：相同的属性词条可以通过熔炼替换，且必须是同部位的熔炼装备
...

Sheet 熔炼属性池
A1: 橙色词条 | B1: [通用] | C1: [青龙] | D1: [白虎] | E1: [朱雀] | F1: [玄武] | G1: [狂战] | H1: [霸刀] | I1: [武圣] | J1: [魔刃] | K1: [七杀] | L1: [破军] | M1: [霸王] | N1: [贪狼] | O1: [技师] | P1: [天翔] | Q1: [魔羽] | R1: [影杀] | S1: [术士] | T1: [斗魂] | U1: [幻魔] | V1: [鬼狩]
A2: 物理、法术攻击力 | G2: =_xlfn.CONCAT(熔炼属性池!G$1,熔炼属性池!$A2) -> [狂战]物理、法术攻击力 | H2: =_xlfn.CONCAT(熔炼属性池!H$1,熔炼属性池!$A2) -> [霸刀]物理、法术攻击力 | I2: =_xlfn.CONCAT(熔炼属性池!I$1,熔炼属性池!$A2) -> [武圣]物理、法术攻击力 | J2: =_xlfn.CONCAT(熔炼属性池!J$1,熔炼属性池!$A2) -> [魔刃]物理、法术攻击力 | K2: =_xlfn.CONCAT(熔炼属性池!K$1,熔炼属性池!$A2) -> [七杀]物理、法术攻击力 | L2: =_xlfn.CONCAT(熔炼属性池!L$1,熔炼属性池!$A2) -> [破军]物理、法术攻击力 | M2: =_xlfn.CONCAT(熔炼属性池!M$1,熔炼属性池!$A2) -> [霸王]物理、法术攻击力 | N2: =_xlfn.CONCAT(熔炼属性池!N$1,熔炼属性池!$A2) -> [贪狼]物理、法术攻击力 | ... V2: =_xlfn.CONCAT(熔炼属性池!V$1,熔炼属性池!$A2) -> [鬼狩]物理、法术攻击力
A3: 攻击加持 | G3: =_xlfn.CONCAT(熔炼属性池!G$1,熔炼属性池!$A3) -> [狂战]攻击加持 | H3: =_xlfn.CONCAT(熔炼属性池!H$1,熔炼属性池!$A3) -> [霸刀]攻击加持 | I3: =_xlfn.CONCAT(熔炼属性池!I$1,熔炼属性池!$A3) -> [武圣]攻击加持 | J3: =_xlfn.CONCAT(熔炼属性池!J$1,熔炼属性池!$A3) -> [魔刃]攻击加持 | K3: =_xlfn.CONCAT(熔炼属性池!K$1,熔炼属性池!$A3) -> [七杀]攻击加持 | L3: =_xlfn.CONCAT(熔炼属性池!L$1,熔炼属性池!$A3) -> [破军]攻击加持 | M3: =_xlfn.CONCAT(熔炼属性池!M$1,熔炼属性池!$A3) -> [霸王]攻击加持 | N3: =_xlfn.CONCAT(熔炼属性池!N$1,熔炼属性池!$A3) -> [贪狼]攻击加持 | ... V3: =_xlfn.CONCAT(熔炼属性池!V$1,熔炼属性池!$A3) -> [鬼狩]攻击加持
A4: 武力、智力 | G4: =_xlfn.CONCAT(熔炼属性池!G$1,熔炼属性池!$A4) -> [狂战]武力、智力 | H4: =_xlfn.CONCAT(熔炼属性池!H$1,熔炼属性池!$A4) -> [霸刀]武力、智力 | I4: =_xlfn.CONCAT(熔炼属性池!I$1,熔炼属性池!$A4) -> [武圣]武力、智力 | J4: =_xlfn.CONCAT(熔炼属性池!J$1,熔炼属性池!$A4) -> [魔刃]武力、智力 | K4: =_xlfn.CONCAT(熔炼属性池!K$1,熔炼属性池!$A4) -> [七杀]武力、智力 | L4: =_xlfn.CONCAT(熔炼属性池!L$1,熔炼属性池!$A4) -> [破军]武力、智力 | M4: =_xlfn.CONCAT(熔炼属性池!M$1,熔炼属性池!$A4) -> [霸王]武力、智力 | N4: =_xlfn.CONCAT(熔炼属性池!N$1,熔炼属性池!$A4) -> [贪狼]武力、智力 | ... V4: =_xlfn.CONCAT(熔炼属性池!V$1,熔炼属性池!$A4) -> [鬼狩]武力、智力
A5: 致命伤害 | G5: =_xlfn.CONCAT(熔炼属性池!G$1,熔炼属性池!$A5) -> [狂战]致命伤害 | H5: =_xlfn.CONCAT(熔炼属性池!H$1,熔炼属性池!$A5) -> [霸刀]致命伤害 | I5: =_xlfn.CONCAT(熔炼属性池!I$1,熔炼属性池!$A5) -> [武圣]致命伤害 | J5: =_xlfn.CONCAT(熔炼属性池!J$1,熔炼属性池!$A5) -> [魔刃]致命伤害 | K5: =_xlfn.CONCAT(熔炼属性池!K$1,熔炼属性池!$A5) -> [七杀]致命伤害 | L5: =_xlfn.CONCAT(熔炼属性池!L$1,熔炼属性池!$A5) -> [破军]致命伤害 | M5: =_xlfn.CONCAT(熔炼属性池!M$1,熔炼属性池!$A5) -> [霸王]致命伤害 | N5: =_xlfn.CONCAT(熔炼属性池!N$1,熔炼属性池!$A5) -> [贪狼]致命伤害 | ... V5: =_xlfn.CONCAT(熔炼属性池!V$1,熔炼属性池!$A5) -> [鬼狩]致命伤害
A6: 光属性伤害 | G6: =_xlfn.CONCAT(熔炼属性池!G$1,熔炼属性池!$A6) -> [狂战]光属性伤害 | H6: =_xlfn.CONCAT(熔炼属性池!H$1,熔炼属性池!$A6) -> [霸刀]光属性伤害 | I6: =_xlfn.CONCAT(熔炼属性池!I$1,熔炼属性池!$A6) -> [武圣]光属性伤害 | J6: =_xlfn.CONCAT(熔炼属性池!J$1,熔炼属性池!$A6) -> [魔刃]光属性伤害 | K6: =_xlfn.CONCAT(熔炼属性池!K$1,熔炼属性池!$A6) -> [七杀]光属性伤害 | L6: =_xlfn.CONCAT(熔炼属性池!L$1,熔炼属性池!$A6) -> [破军]光属性伤害 | M6: =_xlfn.CONCAT(熔炼属性池!M$1,熔炼属性池!$A6) -> [霸王]光属性伤害 | N6: =_xlfn.CONCAT(熔炼属性池!N$1,熔炼属性池!$A6) -> [贪狼]光属性伤害 | ... V6: =_xlfn.CONCAT(熔炼属性池!V$1,熔炼属性池!$A6) -> [鬼狩]光属性伤害
A7: 暗属性伤害 | G7: =_xlfn.CONCAT(熔炼属性池!G$1,熔炼属性池!$A7) -> [狂战]暗属性伤害 | H7: =_xlfn.CONCAT(熔炼属性池!H$1,熔炼属性池!$A7) -> [霸刀]暗属性伤害 | I7: =_xlfn.CONCAT(熔炼属性池!I$1,熔炼属性池!$A7) -> [武圣]暗属性伤害 | J7: =_xlfn.CONCAT(熔炼属性池!J$1,熔炼属性池!$A7) -> [魔刃]暗属性伤害 | K7: =_xlfn.CONCAT(熔炼属性池!K$1,熔炼属性池!$A7) -> [七杀]暗属性伤害 | L7: =_xlfn.CONCAT(熔炼属性池!L$1,熔炼属性池!$A7) -> [破军]暗属性伤害 | M7: =_xlfn.CONCAT(熔炼属性池!M$1,熔炼属性池!$A7) -> [霸王]暗属性伤害 | N7: =_xlfn.CONCAT(熔炼属性池!N$1,熔炼属性池!$A7) -> [贪狼]暗属性伤害 | ... V7: =_xlfn.CONCAT(熔炼属性池!V$1,熔炼属性池!$A7) -> [鬼狩]暗属性伤害
A8: 火属性伤害 | G8: =_xlfn.CONCAT(熔炼属性池!G$1,熔炼属性池!$A8) -> [狂战]火属性伤害 | H8: =_xlfn.CONCAT(熔炼属性池!H$1,熔炼属性池!$A8) -> [霸刀]火属性伤害 | I8: =_xlfn.CONCAT(熔炼属性池!I$1,熔炼属性池!$A8) -> [武圣]火属性伤害 | J8: =_xlfn.CONCAT(熔炼属性池!J$1,熔炼属性池!$A8) -> [魔刃]火属性伤害 | K8: =_xlfn.CONCAT(熔炼属性池!K$1,熔炼属性池!$A8) -> [七杀]火属性伤害 | L8: =_xlfn.CONCAT(熔炼属性池!L$1,熔炼属性池!$A8) -> [破军]火属性伤害 | M8: =_xlfn.CONCAT(熔炼属性池!M$1,熔炼属性池!$A8) -> [霸王]火属性伤害 | N8: =_xlfn.CONCAT(熔炼属性池!N$1,熔炼属性池!$A8) -> [贪狼]火属性伤害 | ... V8: =_xlfn.CONCAT(熔炼属性池!V$1,熔炼属性池!$A8) -> [鬼狩]火属性伤害
A9: 水属性伤害 | G9: =_xlfn.CONCAT(熔炼属性池!G$1,熔炼属性池!$A9) -> [狂战]水属性伤害 | H9: =_xlfn.CONCAT(熔炼属性池!H$1,熔炼属性池!$A9) -> [霸刀]水属性伤害 | I9: =_xlfn.CONCAT(熔炼属性池!I$1,熔炼属性池!$A9) -> [武圣]水属性伤害 | J9: =_xlfn.CONCAT(熔炼属性池!J$1,熔炼属性池!$A9) -> [魔刃]水属性伤害 | K9: =_xlfn.CONCAT(熔炼属性池!K$1,熔炼属性池!$A9) -> [七杀]水属性伤害 | L9: =_xlfn.CONCAT(熔炼属性池!L$1,熔炼属性池!$A9) -> [破军]水属性伤害 | M9: =_xlfn.CONCAT(熔炼属性池!M$1,熔炼属性池!$A9) -> [霸王]水属性伤害 | N9: =_xlfn.CONCAT(熔炼属性池!N$1,熔炼属性池!$A9) -> [贪狼]水属性伤害 | ... V9: =_xlfn.CONCAT(熔炼属性池!V$1,熔炼属性池!$A9) -> [鬼狩]水属性伤害
A10: 刚毅 | G10: =_xlfn.CONCAT(熔炼属性池!G$1,熔炼属性池!$A10) -> [狂战]刚毅 | H10: =_xlfn.CONCAT(熔炼属性池!H$1,熔炼属性池!$A10) -> [霸刀]刚毅 | I10: =_xlfn.CONCAT(熔炼属性池!I$1,熔炼属性池!$A10) -> [武圣]刚毅 | J10: =_xlfn.CONCAT(熔炼属性池!J$1,熔炼属性池!$A10) -> [魔刃]刚毅 | K10: =_xlfn.CONCAT(熔炼属性池!K$1,熔炼属性池!$A10) -> [七杀]刚毅 | L10: =_xlfn.CONCAT(熔炼属性池!L$1,熔炼属性池!$A10) -> [破军]刚毅 | M10: =_xlfn.CONCAT(熔炼属性池!M$1,熔炼属性池!$A10) -> [霸王]刚毅 | N10: =_xlfn.CONCAT(熔炼属性池!N$1,熔炼属性池!$A10) -> [贪狼]刚毅 | ... V10: =_xlfn.CONCAT(熔炼属性池!V$1,熔炼属性池!$A10) -> [鬼狩]刚毅
A11: 韧性 | G11: =_xlfn.CONCAT(熔炼属性池!G$1,熔炼属性池!$A11) -> [狂战]韧性 | H11: =_xlfn.CONCAT(熔炼属性池!H$1,熔炼属性池!$A11) -> [霸刀]韧性 | I11: =_xlfn.CONCAT(熔炼属性池!I$1,熔炼属性池!$A11) -> [武圣]韧性 | J11: =_xlfn.CONCAT(熔炼属性池!J$1,熔炼属性池!$A11) -> [魔刃]韧性 | K11: =_xlfn.CONCAT(熔炼属性池!K$1,熔炼属性池!$A11) -> [七杀]韧性 | L11: =_xlfn.CONCAT(熔炼属性池!L$1,熔炼属性池!$A11) -> [破军]韧性 | M11: =_xlfn.CONCAT(熔炼属性池!M$1,熔炼属性池!$A11) -> [霸王]韧性 | N11: =_xlfn.CONCAT(熔炼属性池!N$1,熔炼属性池!$A11) -> [贪狼]韧性 | ... V11: =_xlfn.CONCAT(熔炼属性池!V$1,熔炼属性池!$A11) -> [鬼狩]韧性
A12: 稳固 | G12: =_xlfn.CONCAT(熔炼属性池!G$1,熔炼属性池!$A12) -> [狂战]稳固 | H12: =_xlfn.CONCAT(熔炼属性池!H$1,熔炼属性池!$A12) -> [霸刀]稳固 | I12: =_xlfn.CONCAT(熔炼属性池!I$1,熔炼属性池!$A12) -> [武圣]稳固 | J12: =_xlfn.CONCAT(熔炼属性池!J$1,熔炼属性池!$A12) -> [魔刃]稳固 | K12: =_xlfn.CONCAT(熔炼属性池!K$1,熔炼属性池!$A12) -> [七杀]稳固 | L12: =_xlfn.CONCAT(熔炼属性池!L$1,熔炼属性池!$A12) -> [破军]稳固 | M12: =_xlfn.CONCAT(熔炼属性池!M$1,熔炼属性池!$A12) -> [霸王]稳固 | N12: =_xlfn.CONCAT(熔炼属性池!N$1,熔炼属性池!$A12) -> [贪狼]稳固 | ... V12: =_xlfn.CONCAT(熔炼属性池!V$1,熔炼属性池!$A12) -> [鬼狩]稳固
A13: 格挡 | G13: =_xlfn.CONCAT(熔炼属性池!G$1,熔炼属性池!$A13) -> [狂战]格挡 | H13: =_xlfn.CONCAT(熔炼属性池!H$1,熔炼属性池!$A13) -> [霸刀]格挡 | I13: =_xlfn.CONCAT(熔炼属性池!I$1,熔炼属性池!$A13) -> [武圣]格挡 | J13: =_xlfn.CONCAT(熔炼属性池!J$1,熔炼属性池!$A13) -> [魔刃]格挡 | K13: =_xlfn.CONCAT(熔炼属性池!K$1,熔炼属性池!$A13) -> [七杀]格挡 | L13: =_xlfn.CONCAT(熔炼属性池!L$1,熔炼属性池!$A13) -> [破军]格挡 | M13: =_xlfn.CONCAT(熔炼属性池!M$1,熔炼属性池!$A13) -> [霸王]格挡 | N13: =_xlfn.CONCAT(熔炼属性池!N$1,熔炼属性池!$A13) -> [贪狼]格挡 | ... V13: =_xlfn.CONCAT(熔炼属性池!V$1,熔炼属性池!$A13) -> [鬼狩]格挡
... A17: 防御加持 | G17: =_xlfn.CONCAT(熔炼属性池!G$1,熔炼属性池!$A17) -> [狂战]防御加持 | H17: =_xlfn.CONCAT(熔炼属性池!H$1,熔炼属性池!$A17) -> [霸刀]防御加持 | I17: =_xlfn.CONCAT(熔炼属性池!I$1,熔炼属性池!$A17) -> [武圣]防御加持 | J17: =_xlfn.CONCAT(熔炼属性池!J$1,熔炼属性池!$A17) -> [魔刃]防御加持 | K17: =_xlfn.CONCAT(熔炼属性池!K$1,熔炼属性池!$A17) -> [七杀]防御加持 | L17: =_xlfn.CONCAT(熔炼属性池!L$1,熔炼属性池!$A17) -> [破军]防御加持 | M17: =_xlfn.CONCAT(熔炼属性池!M$1,熔炼属性池!$A17) -> [霸王]防御加持 | N17: =_xlfn.CONCAT(熔炼属性池!N$1,熔炼属性池!$A17) -> [贪狼]防御加持 | ... V17: =_xlfn.CONCAT(熔炼属性池!V$1,熔炼属性池!$A17) -> [鬼狩]防御加持
A18: 绿色词条 | B18: [通用] | C18: [青龙] | D18: [白虎] | E18: [朱雀] | F18: [玄武] | G18: [狂战] | H18: [霸刀] | I18: [武圣] | J18: [魔刃] | K18: [七杀] | L18: [破军] | M18: [霸王] | N18: [贪狼] | O18: [技师] | P18: [天翔] | Q18: [魔羽] | R18: [影杀] | S18: [术士] | T18: [斗魂] | U18: [幻魔] | V18: [鬼狩]
A19: 物理、法术攻击力 | G19: =_xlfn.CONCAT(熔炼属性池!G$1,熔炼属性池!$A19) -> [狂战]物理、法术攻击力 | H19: =_xlfn.CONCAT(熔炼属性池!H$1,熔炼属性池!$A19) -> [霸刀]物理、法术攻击力 | I19: =_xlfn.CONCAT(熔炼属性池!I$1,熔炼属性池!$A19) -> [武圣]物理、法术攻击力 | J19: =_xlfn.CONCAT(熔炼属性池!J$1,熔炼属性池!$A19) -> [魔刃]物理、法术攻击力 | K19: =_xlfn.CONCAT(熔炼属性池!K$1,熔炼属性池!$A19) -> [七杀]物理、法术攻击力 | L19: =_xlfn.CONCAT(熔炼属性池!L$1,熔炼属性池!$A19) -> [破军]物理、法术攻击力 | M19: =_xlfn.CONCAT(熔炼属性池!M$1,熔炼属性池!$A19) -> [霸王]物理、法术攻击力 | N19: =_xlfn.CONCAT(熔炼属性池!N$1,熔炼属性池!$A19) -> [贪狼]物理、法术攻击力 | ... V19: =_xlfn.CONCAT(熔炼属性池!V$1,熔炼属性池!$A19) -> [鬼狩]物理、法术攻击力
A20: 攻击加持 | G20: =_xlfn.CONCAT(熔炼属性池!G$1,熔炼属性池!$A20) -> [狂战]攻击加持 | H20: =_xlfn.CONCAT(熔炼属性池!H$1,熔炼属性池!$A20) -> [霸刀]攻击加持 | I20: =_xlfn.CONCAT(熔炼属性池!I$1,熔炼属性池!$A20) -> [武圣]攻击加持 | J20: =_xlfn.CONCAT(熔炼属性池!J$1,熔炼属性池!$A20) -> [魔刃]攻击加持 | K20: =_xlfn.CONCAT(熔炼属性池!K$1,熔炼属性池!$A20) -> [七杀]攻击加持 | L20: =_xlfn.CONCAT(熔炼属性池!L$1,熔炼属性池!$A20) -> [破军]攻击加持 | M20: =_xlfn.CONCAT(熔炼属性池!M$1,熔炼属性池!$A20) -> [霸王]攻击加持 | N20: =_xlfn.CONCAT(熔炼属性池!N$1,熔炼属性池!$A20) -> [贪狼]攻击加持 | ... V20: =_xlfn.CONCAT(熔炼属性池!V$1,熔炼属性池!$A20) -> [鬼狩]攻击加持
A21: 武力、智力 | G21: =_xlfn.CONCAT(熔炼属性池!G$1,熔炼属性池!$A21) -> [狂战]武力、智力 | H21: =_xlfn.CONCAT(熔炼属性池!H$1,熔炼属性池!$A21) -> [霸刀]武力、智力 | I21: =_xlfn.CONCAT(熔炼属性池!I$1,熔炼属性池!$A21) -> [武圣]武力、智力 | J21: =_xlfn.CONCAT(熔炼属性池!J$1,熔炼属性池!$A21) -> [魔刃]武力、智力 | K21: =_xlfn.CONCAT(熔炼属性池!K$1,熔炼属性池!$A21) -> [七杀]武力、智力 | L21: =_xlfn.CONCAT(熔炼属性池!L$1,熔炼属性池!$A21) -> [破军]武力、智力 | M21: =_xlfn.CONCAT(熔炼属性池!M$1,熔炼属性池!$A21) -> [霸王]武力、智力 | N21: =_xlfn.CONCAT(熔炼属性池!N$1,熔炼属性池!$A21) -> [贪狼]武力、智力 | ... V21: =_xlfn.CONCAT(熔炼属性池!V$1,熔炼属性池!$A21) -> [鬼狩]武力、智力
A22: 致命伤害 | G22: =_xlfn.CONCAT(熔炼属性池!G$1,熔炼属性池!$A22) -> [狂战]致命伤害 | H22: =_xlfn.CONCAT(熔炼属性池!H$1,熔炼属性池!$A22) -> [霸刀]致命伤害 | I22: =_xlfn.CONCAT(熔炼属性池!I$1,熔炼属性池!$A22) -> [武圣]致命伤害 | J22: =_xlfn.CONCAT(熔炼属性池!J$1,熔炼属性池!$A22) -> [魔刃]致命伤害 | K22: =_xlfn.CONCAT(熔炼属性池!K$1,熔炼属性池!$A22) -> [七杀]致命伤害 | L22: =_xlfn.CONCAT(熔炼属性池!L$1,熔炼属性池!$A22) -> [破军]致命伤害 | M22: =_xlfn.CONCAT(熔炼属性池!M$1,熔炼属性池!$A22) -> [霸王]致命伤害 | N22: =_xlfn.CONCAT(熔炼属性池!N$1,熔炼属性池!$A22) -> [贪狼]致命伤害 | ... V22: =_xlfn.CONCAT(熔炼属性池!V$1,熔炼属性池!$A22) -> [鬼狩]致命伤害
A23: 光属性伤害 | G23: =_xlfn.CONCAT(熔炼属性池!G$1,熔炼属性池!$A23) -> [狂战]光属性伤害 | H23: =_xlfn.CONCAT(熔炼属性池!H$1,熔炼属性池!$A23) -> [霸刀]光属性伤害 | I23: =_xlfn.CONCAT(熔炼属性池!I$1,熔炼属性池!$A23) -> [武圣]光属性伤害 | J23: =_xlfn.CONCAT(熔炼属性池!J$1,熔炼属性池!$A23) -> [魔刃]光属性伤害 | K23: =_xlfn.CONCAT(熔炼属性池!K$1,熔炼属性池!$A23) -> [七杀]光属性伤害 | L23: =_xlfn.CONCAT(熔炼属性池!L$1,熔炼属性池!$A23) -> [破军]光属性伤害 | M23: =_xlfn.CONCAT(熔炼属性池!M$1,熔炼属性池!$A23) -> [霸王]光属性伤害 | N23: =_xlfn.CONCAT(熔炼属性池!N$1,熔炼属性池!$A23) -> [贪狼]光属性伤害 | ... V23: =_xlfn.CONCAT(熔炼属性池!V$1,熔炼属性池!$A23) -> [鬼狩]光属性伤害
A24: 暗属性伤害 | G24: =_xlfn.CONCAT(熔炼属性池!G$1,熔炼属性池!$A24) -> [狂战]暗属性伤害 | H24: =_xlfn.CONCAT(熔炼属性池!H$1,熔炼属性池!$A24) -> [霸刀]暗属性伤害 | I24: =_xlfn.CONCAT(熔炼属性池!I$1,熔炼属性池!$A24) -> [武圣]暗属性伤害 | J24: =_xlfn.CONCAT(熔炼属性池!J$1,熔炼属性池!$A24) -> [魔刃]暗属性伤害 | K24: =_xlfn.CONCAT(熔炼属性池!K$1,熔炼属性池!$A24) -> [七杀]暗属性伤害 | L24: =_xlfn.CONCAT(熔炼属性池!L$1,熔炼属性池!$A24) -> [破军]暗属性伤害 | M24: =_xlfn.CONCAT(熔炼属性池!M$1,熔炼属性池!$A24) -> [霸王]暗属性伤害 | N24: =_xlfn.CONCAT(熔炼属性池!N$1,熔炼属性池!$A24) -> [贪狼]暗属性伤害 | ... V24: =_xlfn.CONCAT(熔炼属性池!V$1,熔炼属性池!$A24) -> [鬼狩]暗属性伤害
A25: 火属性伤害 | G25: =_xlfn.CONCAT(熔炼属性池!G$1,熔炼属性池!$A25) -> [狂战]火属性伤害 | H25: =_xlfn.CONCAT(熔炼属性池!H$1,熔炼属性池!$A25) -> [霸刀]火属性伤害 | I25: =_xlfn.CONCAT(熔炼属性池!I$1,熔炼属性池!$A25) -> [武圣]火属性伤害 | J25: =_xlfn.CONCAT(熔炼属性池!J$1,熔炼属性池!$A25) -> [魔刃]火属性伤害 | K25: =_xlfn.CONCAT(熔炼属性池!K$1,熔炼属性池!$A25) -> [七杀]火属性伤害 | L25: =_xlfn.CONCAT(熔炼属性池!L$1,熔炼属性池!$A25) -> [破军]火属性伤害 | M25: =_xlfn.CONCAT(熔炼属性池!M$1,熔炼属性池!$A25) -> [霸王]火属性伤害 | N25: =_xlfn.CONCAT(熔炼属性池!N$1,熔炼属性池!$A25) -> [贪狼]火属性伤害 | ... V25: =_xlfn.CONCAT(熔炼属性池!V$1,熔炼属性池!$A25) -> [鬼狩]火属性伤害
A26: 水属性伤害 | G26: =_xlfn.CONCAT(熔炼属性池!G$1,熔炼属性池!$A26) -> [狂战]水属性伤害 | H26: =_xlfn.CONCAT(熔炼属性池!H$1,熔炼属性池!$A26) -> [霸刀]水属性伤害 | I26: =_xlfn.CONCAT(熔炼属性池!I$1,熔炼属性池!$A26) -> [武圣]水属性伤害 | J26: =_xlfn.CONCAT(熔炼属性池!J$1,熔炼属性池!$A26) -> [魔刃]水属性伤害 | K26: =_xlfn.CONCAT(熔炼属性池!K$1,熔炼属性池!$A26) -> [七杀]水属性伤害 | L26: =_xlfn.CONCAT(熔炼属性池!L$1,熔炼属性池!$A26) -> [破军]水属性伤害 | M26: =_xlfn.CONCAT(熔炼属性池!M$1,熔炼属性池!$A26) -> [霸王]水属性伤害 | N26: =_xlfn.CONCAT(熔炼属性池!N$1,熔炼属性池!$A26) -> [贪狼]水属性伤害 | ... V26: =_xlfn.CONCAT(熔炼属性池!V$1,熔炼属性池!$A26) -> [鬼狩]水属性伤害
A27: 刚毅 | G27: =_xlfn.CONCAT(熔炼属性池!G$1,熔炼属性池!$A27) -> [狂战]刚毅 | H27: =_xlfn.CONCAT(熔炼属性池!H$1,熔炼属性池!$A27) -> [霸刀]刚毅 | I27: =_xlfn.CONCAT(熔炼属性池!I$1,熔炼属性池!$A27) -> [武圣]刚毅 | J27: =_xlfn.CONCAT(熔炼属性池!J$1,熔炼属性池!$A27) -> [魔刃]刚毅 | K27: =_xlfn.CONCAT(熔炼属性池!K$1,熔炼属性池!$A27) -> [七杀]刚毅 | L27: =_xlfn.CONCAT(熔炼属性池!L$1,熔炼属性池!$A27) -> [破军]刚毅 | M27: =_xlfn.CONCAT(熔炼属性池!M$1,熔炼属性池!$A27) -> [霸王]刚毅 | N27: =_xlfn.CONCAT(熔炼属性池!N$1,熔炼属性池!$A27) -> [贪狼]刚毅 | ... V27: =_xlfn.CONCAT(熔炼属性池!V$1,熔炼属性池!$A27) -> [鬼狩]刚毅
A28: 韧性 | G28: =_xlfn.CONCAT(熔炼属性池!G$1,熔炼属性池!$A28) -> [狂战]韧性 | H28: =_xlfn.CONCAT(熔炼属性池!H$1,熔炼属性池!$A28) -> [霸刀]韧性 | I28: =_xlfn.CONCAT(熔炼属性池!I$1,熔炼属性池!$A28) -> [武圣]韧性 | J28: =_xlfn.CONCAT(熔炼属性池!J$1,熔炼属性池!$A28) -> [魔刃]韧性 | K28: =_xlfn.CONCAT(熔炼属性池!K$1,熔炼属性池!$A28) -> [七杀]韧性 | L28: =_xlfn.CONCAT(熔炼属性池!L$1,熔炼属性池!$A28) -> [破军]韧性 | M28: =_xlfn.CONCAT(熔炼属性池!M$1,熔炼属性池!$A28) -> [霸王]韧性 | N28: =_xlfn.CONCAT(熔炼属性池!N$1,熔炼属性池!$A28) -> [贪狼]韧性 | ... V28: =_xlfn.CONCAT(熔炼属性池!V$1,熔炼属性池!$A28) -> [鬼狩]韧性
A29: 稳固 | G29: =_xlfn.CONCAT(熔炼属性池!G$1,熔炼属性池!$A29) -> [狂战]稳固 | H29: =_xlfn.CONCAT(熔炼属性池!H$1,熔炼属性池!$A29) -> [霸刀]稳固 | I29: =_xlfn.CONCAT(熔炼属性池!I$1,熔炼属性池!$A29) -> [武圣]稳固 | J29: =_xlfn.CONCAT(熔炼属性池!J$1,熔炼属性池!$A29) -> [魔刃]稳固 | K29: =_xlfn.CONCAT(熔炼属性池!K$1,熔炼属性池!$A29) -> [七杀]稳固 | L29: =_xlfn.CONCAT(熔炼属性池!L$1,熔炼属性池!$A29) -> [破军]稳固 | M29: =_xlfn.CONCAT(熔炼属性池!M$1,熔炼属性池!$A29) -> [霸王]稳固 | N29: =_xlfn.CONCAT(熔炼属性池!N$1,熔炼属性池!$A29) -> [贪狼]稳固 | ... V29: =_xlfn.CONCAT(熔炼属性池!V$1,熔炼属性池!$A29) -> [鬼狩]稳固
A30: 格挡 | G30: =_xlfn.CONCAT(熔炼属性池!G$1,熔炼属性池!$A30) -> [狂战]格挡 | H30: =_xlfn.CONCAT(熔炼属性池!H$1,熔炼属性池!$A30) -> [霸刀]格挡 | I30: =_xlfn.CONCAT(熔炼属性池!I$1,熔炼属性池!$A30) -> [武圣]格挡 | J30: =_xlfn.CONCAT(熔炼属性池!J$1,熔炼属性池!$A30) -> [魔刃]格挡 | K30: =_xlfn.CONCAT(熔炼属性池!K$1,熔炼属性池!$A30) -> [七杀]格挡 | L30: =_xlfn.CONCAT(熔炼属性池!L$1,熔炼属性池!$A30) -> [破军]格挡 | M30: =_xlfn.CONCAT(熔炼属性池!M$1,熔炼属性池!$A30) -> [霸王]格挡 | N30: =_xlfn.CONCAT(熔炼属性池!N$1,熔炼属性池!$A30) -> [贪狼]格挡 | ... V30: =_xlfn.CONCAT(熔炼属性池!V$1,熔炼属性池!$A30) -> [鬼狩]格挡
... A34: 防御加持 | G34: =_xlfn.CONCAT(熔炼属性池!G$1,熔炼属性池!$A34) -> [狂战]防御加持 | H34: =_xlfn.CONCAT(熔炼属性池!H$1,熔炼属性池!$A34) -> [霸刀]防御加持 | I34: =_xlfn.CONCAT(熔炼属性池!I$1,熔炼属性池!$A34) -> [武圣]防御加持 | J34: =_xlfn.CONCAT(熔炼属性池!J$1,熔炼属性池!$A34) -> [魔刃]防御加持 | K34: =_xlfn.CONCAT(熔炼属性池!K$1,熔炼属性池!$A34) -> [七杀]防御加持 | L34: =_xlfn.CONCAT(熔炼属性池!L$1,熔炼属性池!$A34) -> [破军]防御加持 | M34: =_xlfn.CONCAT(熔炼属性池!M$1,熔炼属性池!$A34) -> [霸王]防御加持 | N34: =_xlfn.CONCAT(熔炼属性池!N$1,熔炼属性池!$A34) -> [贪狼]防御加持 | ... V34: =_xlfn.CONCAT(熔炼属性池!V$1,熔炼属性池!$A34) -> [鬼狩]防御加持
A35: 紫色词条 | B35: [通用] | C35: [青龙] | D35: [白虎] | E35: [朱雀] | F35: [玄武] | G35: [狂战] | H35: [霸刀] | I35: [武圣] | J35: [魔刃] | K35: [七杀] | L35: [破军] | M35: [霸王] | N35: [贪狼] | O35: [技师] | P35: [天翔] | Q35: [魔羽] | R35: [影杀] | S35: [术士] | T35: [斗魂] | U35: [幻魔] | V35: [鬼狩]
A36: 物理、法术攻击力 | C36: =_xlfn.CONCAT(熔炼属性池!C$1,熔炼属性池!$A36) -> [青龙]物理、法术攻击力 | D36: =_xlfn.CONCAT(熔炼属性池!D$1,熔炼属性池!$A36) -> [白虎]物理、法术攻击力 | E36: =_xlfn.CONCAT(熔炼属性池!E$1,熔炼属性池!$A36) -> [朱雀]物理、法术攻击力 | F36: =_xlfn.CONCAT(熔炼属性池!F$1,熔炼属性池!$A36) -> [玄武]物理、法术攻击力 | G36: =_xlfn.CONCAT(熔炼属性池!G$1,熔炼属性池!$A36) -> [狂战]物理、法术攻击力 | H36: =_xlfn.CONCAT(熔炼属性池!H$1,熔炼属性池!$A36) -> [霸刀]物理、法术攻击力 | I36: =_xlfn.CONCAT(熔炼属性池!I$1,熔炼属性池!$A36) -> [武圣]物理、法术攻击力 | J36: =_xlfn.CONCAT(熔炼属性池!J$1,熔炼属性池!$A36) -> [魔刃]物理、法术攻击力 | ... V36: =_xlfn.CONCAT(熔炼属性池!V$1,熔炼属性池!$A36) -> [鬼狩]物理、法术攻击力
A37: 攻击加持 | C37: =_xlfn.CONCAT(熔炼属性池!C$1,熔炼属性池!$A37) -> [青龙]攻击加持 | D37: =_xlfn.CONCAT(熔炼属性池!D$1,熔炼属性池!$A37) -> [白虎]攻击加持 | E37: =_xlfn.CONCAT(熔炼属性池!E$1,熔炼属性池!$A37) -> [朱雀]攻击加持 | F37: =_xlfn.CONCAT(熔炼属性池!F$1,熔炼属性池!$A37) -> [玄武]攻击加持 | G37: =_xlfn.CONCAT(熔炼属性池!G$1,熔炼属性池!$A37) -> [狂战]攻击加持 | H37: =_xlfn.CONCAT(熔炼属性池!H$1,熔炼属性池!$A37) -> [霸刀]攻击加持 | I37: =_xlfn.CONCAT(熔炼属性池!I$1,熔炼属性池!$A37) -> [武圣]攻击加持 | J37: =_xlfn.CONCAT(熔炼属性池!J$1,熔炼属性池!$A37) -> [魔刃]攻击加持 | ... V37: =_xlfn.CONCAT(熔炼属性池!V$1,熔炼属性池!$A37) -> [鬼狩]攻击加持
A38: 武力、智力 | C38: =_xlfn.CONCAT(熔炼属性池!C$1,熔炼属性池!$A38) -> [青龙]武力、智力 | D38: =_xlfn.CONCAT(熔炼属性池!D$1,熔炼属性池!$A38) -> [白虎]武力、智力 | E38: =_xlfn.CONCAT(熔炼属性池!E$1,熔炼属性池!$A38) -> [朱雀]武力、智力 | F38: =_xlfn.CONCAT(熔炼属性池!F$1,熔炼属性池!$A38) -> [玄武]武力、智力 | G38: =_xlfn.CONCAT(熔炼属性池!G$1,熔炼属性池!$A38) -> [狂战]武力、智力 | H38: =_xlfn.CONCAT(熔炼属性池!H$1,熔炼属性池!$A38) -> [霸刀]武力、智力 | I38: =_xlfn.CONCAT(熔炼属性池!I$1,熔炼属性池!$A38) -> [武圣]武力、智力 | J38: =_xlfn.CONCAT(熔炼属性池!J$1,熔炼属性池!$A38) -> [魔刃]武力、智力 | ... V38: =_xlfn.CONCAT(熔炼属性池!V$1,熔炼属性池!$A38) -> [鬼狩]武力、智力
A39: 致命伤害 | C39: =_xlfn.CONCAT(熔炼属性池!C$1,熔炼属性池!$A39) -> [青龙]致命伤害 | D39: =_xlfn.CONCAT(熔炼属性池!D$1,熔炼属性池!$A39) -> [白虎]致命伤害 | E39: =_xlfn.CONCAT(熔炼属性池!E$1,熔炼属性池!$A39) -> [朱雀]致命伤害 | F39: =_xlfn.CONCAT(熔炼属性池!F$1,熔炼属性池!$A39) -> [玄武]致命伤害 | G39: =_xlfn.CONCAT(熔炼属性池!G$1,熔炼属性池!$A39) -> [狂战]致命伤害 | H39: =_xlfn.CONCAT(熔炼属性池!H$1,熔炼属性池!$A39) -> [霸刀]致命伤害 | I39: =_xlfn.CONCAT(熔炼属性池!I$1,熔炼属性池!$A39) -> [武圣]致命伤害 | J39: =_xlfn.CONCAT(熔炼属性池!J$1,熔炼属性池!$A39) -> [魔刃]致命伤害 | ... V39: =_xlfn.CONCAT(熔炼属性池!V$1,熔炼属性池!$A39) -> [鬼狩]致命伤害
A40: 光属性伤害 | C40: =_xlfn.CONCAT(熔炼属性池!C$1,熔炼属性池!$A40) -> [青龙]光属性伤害 | D40: =_xlfn.CONCAT(熔炼属性池!D$1,熔炼属性池!$A40) -> [白虎]光属性伤害 | E40: =_xlfn.CONCAT(熔炼属性池!E$1,熔炼属性池!$A40) -> [朱雀]光属性伤害 | F40: =_xlfn.CONCAT(熔炼属性池!F$1,熔炼属性池!$A40) -> [玄武]光属性伤害 | G40: =_xlfn.CONCAT(熔炼属性池!G$1,熔炼属性池!$A40) -> [狂战]光属性伤害 | H40: =_xlfn.CONCAT(熔炼属性池!H$1,熔炼属性池!$A40) -> [霸刀]光属性伤害 | I40: =_xlfn.CONCAT(熔炼属性池!I$1,熔炼属性池!$A40) -> [武圣]光属性伤害 | J40: =_xlfn.CONCAT(熔炼属性池!J$1,熔炼属性池!$A40) -> [魔刃]光属性伤害 | ... V40: =_xlfn.CONCAT(熔炼属性池!V$1,熔炼属性池!$A40) -> [鬼狩]光属性伤害
A41: 暗属性伤害 | C41: =_xlfn.CONCAT(熔炼属性池!C$1,熔炼属性池!$A41) -> [青龙]暗属性伤害 | D41: =_xlfn.CONCAT(熔炼属性池!D$1,熔炼属性池!$A41) -> [白虎]暗属性伤害 | E41: =_xlfn.CONCAT(熔炼属性池!E$1,熔炼属性池!$A41) -> [朱雀]暗属性伤害 | F41: =_xlfn.CONCAT(熔炼属性池!F$1,熔炼属性池!$A41) -> [玄武]暗属性伤害 | G41: =_xlfn.CONCAT(熔炼属性池!G$1,熔炼属性池!$A41) -> [狂战]暗属性伤害 | H41: =_xlfn.CONCAT(熔炼属性池!H$1,熔炼属性池!$A41) -> [霸刀]暗属性伤害 | I41: =_xlfn.CONCAT(熔炼属性池!I$1,熔炼属性池!$A41) -> [武圣]暗属性伤害 | J41: =_xlfn.CONCAT(熔炼属性池!J$1,熔炼属性池!$A41) -> [魔刃]暗属性伤害 | ... V41: =_xlfn.CONCAT(熔炼属性池!V$1,熔炼属性池!$A41) -> [鬼狩]暗属性伤害
A42: 火属性伤害 | C42: =_xlfn.CONCAT(熔炼属性池!C$1,熔炼属性池!$A42) -> [青龙]火属性伤害 | D42: =_xlfn.CONCAT(熔炼属性池!D$1,熔炼属性池!$A42) -> [白虎]火属性伤害 | E42: =_xlfn.CONCAT(熔炼属性池!E$1,熔炼属性池!$A42) -> [朱雀]火属性伤害 | F42: =_xlfn.CONCAT(熔炼属性池!F$1,熔炼属性池!$A42) -> [玄武]火属性伤害 | G42: =_xlfn.CONCAT(熔炼属性池!G$1,熔炼属性池!$A42) -> [狂战]火属性伤害 | H42: =_xlfn.CONCAT(熔炼属性池!H$1,熔炼属性池!$A42) -> [霸刀]火属性伤害 | I42: =_xlfn.CONCAT(熔炼属性池!I$1,熔炼属性池!$A42) -> [武圣]火属性伤害 | J42: =_xlfn.CONCAT(熔炼属性池!J$1,熔炼属性池!$A42) -> [魔刃]火属性伤害 | ... V42: =_xlfn.CONCAT(熔炼属性池!V$1,熔炼属性池!$A42) -> [鬼狩]火属性伤害
A43: 水属性伤害 | C43: =_xlfn.CONCAT(熔炼属性池!C$1,熔炼属性池!$A43) -> [青龙]水属性伤害 | D43: =_xlfn.CONCAT(熔炼属性池!D$1,熔炼属性池!$A43) -> [白虎]水属性伤害 | E43: =_xlfn.CONCAT(熔炼属性池!E$1,熔炼属性池!$A43) -> [朱雀]水属性伤害 | F43: =_xlfn.CONCAT(熔炼属性池!F$1,熔炼属性池!$A43) -> [玄武]水属性伤害 | G43: =_xlfn.CONCAT(熔炼属性池!G$1,熔炼属性池!$A43) -> [狂战]水属性伤害 | H43: =_xlfn.CONCAT(熔炼属性池!H$1,熔炼属性池!$A43) -> [霸刀]水属性伤害 | I43: =_xlfn.CONCAT(熔炼属性池!I$1,熔炼属性池!$A43) -> [武圣]水属性伤害 | J43: =_xlfn.CONCAT(熔炼属性池!J$1,熔炼属性池!$A43) -> [魔刃]水属性伤害 | ... V43: =_xlfn.CONCAT(熔炼属性池!V$1,熔炼属性池!$A43) -> [鬼狩]水属性伤害
A44: 刚毅 | C44: =_xlfn.CONCAT(熔炼属性池!C$1,熔炼属性池!$A44) -> [青龙]刚毅 | D44: =_xlfn.CONCAT(熔炼属性池!D$1,熔炼属性池!$A44) -> [白虎]刚毅 | E44: =_xlfn.CONCAT(熔炼属性池!E$1,熔炼属性池!$A44) -> [朱雀]刚毅 | F44: =_xlfn.CONCAT(熔炼属性池!F$1,熔炼属性池!$A44) -> [玄武]刚毅 | G44: =_xlfn.CONCAT(熔炼属性池!G$1,熔炼属性池!$A44) -> [狂战]刚毅 | H44: =_xlfn.CONCAT(熔炼属性池!H$1,熔炼属性池!$A44) -> [霸刀]刚毅 | I44: =_xlfn.CONCAT(熔炼属性池!I$1,熔炼属性池!$A44) -> [武圣]刚毅 | J44: =_xlfn.CONCAT(熔炼属性池!J$1,熔炼属性池!$A44) -> [魔刃]刚毅 | ... V44: =_xlfn.CONCAT(熔炼属性池!V$1,熔炼属性池!$A44) -> [鬼狩]刚毅
A45: 韧性 | C45: =_xlfn.CONCAT(熔炼属性池!C$1,熔炼属性池!$A45) -> [青龙]韧性 | D45: =_xlfn.CONCAT(熔炼属性池!D$1,熔炼属性池!$A45) -> [白虎]韧性 | E45: =_xlfn.CONCAT(熔炼属性池!E$1,熔炼属性池!$A45) -> [朱雀]韧性 | F45: =_xlfn.CONCAT(熔炼属性池!F$1,熔炼属性池!$A45) -> [玄武]韧性 | G45: =_xlfn.CONCAT(熔炼属性池!G$1,熔炼属性池!$A45) -> [狂战]韧性 | H45: =_xlfn.CONCAT(熔炼属性池!H$1,熔炼属性池!$A45) -> [霸刀]韧性 | I45: =_xlfn.CONCAT(熔炼属性池!I$1,熔炼属性池!$A45) -> [武圣]韧性 | J45: =_xlfn.CONCAT(熔炼属性池!J$1,熔炼属性池!$A45) -> [魔刃]韧性 | ... V45: =_xlfn.CONCAT(熔炼属性池!V$1,熔炼属性池!$A45) -> [鬼狩]韧性
A46: 稳固 | C46: =_xlfn.CONCAT(熔炼属性池!C$1,熔炼属性池!$A46) -> [青龙]稳固 | D46: =_xlfn.CONCAT(熔炼属性池!D$1,熔炼属性池!$A46) -> [白虎]稳固 | E46: =_xlfn.CONCAT(熔炼属性池!E$1,熔炼属性池!$A46) -> [朱雀]稳固 | F46: =_xlfn.CONCAT(熔炼属性池!F$1,熔炼属性池!$A46) -> [玄武]稳固 | G46: =_xlfn.CONCAT(熔炼属性池!G$1,熔炼属性池!$A46) -> [狂战]稳固 | H46: =_xlfn.CONCAT(熔炼属性池!H$1,熔炼属性池!$A46) -> [霸刀]稳固 | I46: =_xlfn.CONCAT(熔炼属性池!I$1,熔炼属性池!$A46) -> [武圣]稳固 | J46: =_xlfn.CONCAT(熔炼属性池!J$1,熔炼属性池!$A46) -> [魔刃]稳固 | ... V46: =_xlfn.CONCAT(熔炼属性池!V$1,熔炼属性池!$A46) -> [鬼狩]稳固
...

Sheet 装备属性池
C2: 武器 | D2: 项链 | E2: 戒指 | F2: 手镯 | G2: 头盔 | H2: 衣服 | I2: 腰带 | J2: 裤子 | K2: 鞋子 | M2: 套装： | N2: 1 | O2: 2 | P2: 3 | Q2: 4 | R2: 5 | S2: 6 | T2: 7 | U2: 8 | V2: 9
A3: 战力属性 | C3: 熔炼属性 | D3: 熔炼属性 | E3: 熔炼属性 | F3: 熔炼属性 | G3: 熔炼属性 | H3: 熔炼属性 | I3: 熔炼属性 | J3: 熔炼属性 | K3: 熔炼属性 | P3: 生命值 | R3: 防御加持 | T3: 攻击加持 | V3: 物理/法术攻击
A4: PVP属性 | B4: 1 | C4: 物理、法术攻击 | D4: 物理、法术攻击 | E4: 物理、法术攻击 | F4: 物理、法术攻击 | G4: 物理、法术攻击 | H4: 物理、法术攻击 | I4: 物理、法术攻击 | J4: 物理、法术攻击 | K4: 物理、法术攻击 | R4: 黄巾起义 套装 | V4: 1
A5: 基础属性 | B5: 2 | C5: 致命伤害 | D5: 致命伤害 | E5: 致命伤害 | F5: 致命伤害 | G5: 水属性伤害 | H5: 火属性伤害 | I5: 对目标伤害 | J5: 光属性伤害 | K5: 暗属性伤害 | M5: 1 | N5: 武器 第三条 | O5: 从攻击加持 改成 伤害增加 | R5: 1 | S5: 激活熔炼强化属性效果
A6: 防御属性 | B6: 3 | C6: 对目标伤害 | D6: 武力/智力 | E6: 武力/智力 | F6: 武力/智力 | G6: 攻击加持 | H6: 攻击加持 | I6: 攻击加持 | J6: 攻击加持 | K6: 攻击加持 | M6: 2 | N6: 手镯 | O6: 伤害增加 改成 改成致命伤害 | Q6: 0.15 | R6: 2 | S6: 防御力 | T6: 1000
B7: 4 | C7: 破防/破法 | D7: 破防/破法 | E7: 精准/穿透 | F7: 精准/穿透 | G7: 格挡 | H7: 刚毅 | I7: 抵抗 | J7: 韧性 | K7: 稳固 | M7: 3 | N7: 全部攻击力至 | O7: 最大值提升 | P7: 500 | R7: 3 | S7: 防御加持 | T7: 100
C8: 基础属性 | D8: 基础属性 | E8: 基础属性 | F8: 基础属性 | G8: 基础属性 | H8: 基础属性 | I8: 基础属性 | J8: 基础属性 | K8: 基础属性 | M8: 4 | N8: 武力智力 | O8: 最大值 | P8: 200 | R8: 4 | S8: 物理致命 | T8: 0.1
B9: 1 | C9: 物理、法术攻击 | D9: 法力值 | E9: 法力值 | F9: 法力值 | G9: 生命值 | H9: 生命值 | I9: 生命值 | J9: 生命值 | K9: 生命值 | M9: 5 | N9: 加持类型 | O9: 改成万分比 | P9: 数值从10-1000 | Q9: 0.1-10 | R9: 5 | S9: 法术致命 | T9: 0.1
B10: 2 | C10: 物理致命 | D10: 法术防御 | E10: 法术防御 | F10: 法术防御 | G10: 物理防御 | H10: 物理防御 | I10: 物理防御 | J10: 物理防御 | K10: 物理防御 | M10: 6 | N10: 5件防具第3条都改成 攻击加持 | P10: 上限改成10 | R10: 6 | S10: 移动速度 | T10: 0.1
B11: 3 | C11: 法术致命 | D11: 意志 | E11: 意志 | F11: 意志 | G11: 意志 | H11: 体力 | I11: 体力 | J11: 体力 | K11: 体力 | M11: 7 | N11: 8件增加黄巾套装效果 右侧数值（特殊效果程序实现：激活熔炼强化属性效果） | R11: 7 | S11: 攻击速度 | T11: 0.1
F12: 随机值过低 每一项保证随机区间量是100 | M12: 8 | N12: 最大值橙色
A13: 类型 | B13: 属性类型 | C13: 装备等级 | D13: 增长值 | E13: 最低值 | F13: 最高值 | G13: 模拟器 | H13: 增长系数 | I13: 随机量 | J13: 极值 | K13: 强化1 | L13: 强化2 | M13: 强化3 | N13: 强化4 | O13: 强化5 | P13: 强化6 | Q13: 强化7 | R13: 强化8 | S13: 强化9 | T13: 强化10 | U13: 强化11 | V13: 强化12 | W13: 强化13 | X13: 强化14 | Y13: 强化15 | Z13: 强化16 | AA13: 强化17 | AB13: 强化18 | AC13: 强化19 | AD13: 强化20
A14: 战力 | B14: 物理/法术攻击 | C14: 1 | D14: =F14/I14 -> 5 | E14: =D14 -> 5 | F14: =(H14*C14) -> 500 | G14: =F14*9 -> 4500 | H14: 500 | I14: 100 | J14: =F14 -> 500 | K14: =$J14*K$30 -> 520 | L14: =$J14*L$30 -> 540 | M14: =$J14*M$30 -> 560 | N14: =$J14*N$30 -> 580 | O14: =$J14*O$30 -> 620 | P14: =$J14*P$30 -> 660 | Q14: =$J14*Q$30 -> 700 | R14: =$J14*R$30 -> 740 | ... AD14: =$J14*AD$30 -> 2660
A15: 战力 | B15: 武力/智力 | C15: 1 | D15: =F15/I15 -> 2 | E15: =D15 -> 2 | F15: =(H15*C15) -> 200 | G15: =F15*5 -> 1000 | H15: 200 | I15: 100 | J15: =F15 -> 200 | K15: =$J15*K$30 -> 208 | L15: =$J15*L$30 -> 216 | M15: =$J15*M$30 -> 224 | N15: =$J15*N$30 -> 232 | O15: =$J15*O$30 -> 248 | P15: =$J15*P$30 -> 264 | Q15: =$J15*Q$30 -> 280 | R15: =$J15*R$30 -> 296 | ... AD15: =$J15*AD$30 -> 1064
A16: 战力 | B16: 致命伤害+ | C16: 1 | D16: =F16/I16 -> 0.0015 | E16: =D16 -> 0.0015 | F16: =C16*H16 -> 0.15 | G16: =F16*3 -> 0.45 | H16: 0.15 | I16: 100 | J16: =F16 -> 0.15 | K16: =$J16*K$30 -> 0.156 | L16: =$J16*L$30 -> 0.162 | M16: =$J16*M$30 -> 0.168 | N16: =$J16*N$30 -> 0.174 | O16: =$J16*O$30 -> 0.186 | P16: =$J16*P$30 -> 0.198 | Q16: =$J16*Q$30 -> 0.21 | R16: =$J16*R$30 -> 0.222 | ... AD16: =$J16*AD$30 -> 0.798
A17: 战力 | B17: 光属性伤害+ | C17: 1 | D17: =F17/I17 -> 0.001 | E17: =D17 -> 0.001 | F17: =C17*H17 -> 0.1 | H17: 0.1 | I17: 100 | J17: =F17 -> 0.1 | K17: =$J17*K$30 -> 0.104 | L17: =$J17*L$30 -> 0.108 | M17: =$J17*M$30 -> 0.112 | N17: =$J17*N$30 -> 0.116 | O17: =$J17*O$30 -> 0.124 | P17: =$J17*P$30 -> 0.132 | Q17: =$J17*Q$30 -> 0.14 | R17: =$J17*R$30 -> 0.148 | ... AD17: =$J17*AD$30 -> 0.532
A18: 战力 | B18: 暗属性伤害+ | C18: 1 | D18: =F18/I18 -> 0.001 | E18: =D18 -> 0.001 | F18: =C18*H18 -> 0.1 | H18: 0.1 | I18: 100 | J18: =F18 -> 0.1 | K18: =$J18*K$30 -> 0.104 | L18: =$J18*L$30 -> 0.108 | M18: =$J18*M$30 -> 0.112 | N18: =$J18*N$30 -> 0.116 | O18: =$J18*O$30 -> 0.124 | P18: =$J18*P$30 -> 0.132 | Q18: =$J18*Q$30 -> 0.14 | R18: =$J18*R$30 -> 0.148 | ... AD18: =$J18*AD$30 -> 0.532
A19: 战力 | B19: 火属性伤害+ | C19: 1 | D19: =F19/I19 -> 0.001 | E19: =D19 -> 0.001 | F19: =C19*H19 -> 0.1 | H19: 0.1 | I19: 100 | J19: =F19 -> 0.1 | K19: =$J19*K$30 -> 0.104 | L19: =$J19*L$30 -> 0.108 | M19: =$J19*M$30 -> 0.112 | N19: =$J19*N$30 -> 0.116 | O19: =$J19*O$30 -> 0.124 | P19: =$J19*P$30 -> 0.132 | Q19: =$J19*Q$30 -> 0.14 | R19: =$J19*R$30 -> 0.148 | ... AD19: =$J19*AD$30 -> 0.532
A20: 战力 | B20: 水属性伤害+ | C20: 1 | D20: =F20/I20 -> 0.001 | E20: =D20 -> 0.001 | F20: =C20*H20 -> 0.1 | H20: 0.1 | I20: 100 | J20: =F20 -> 0.1 | K20: =$J20*K$30 -> 0.104 | L20: =$J20*L$30 -> 0.108 | M20: =$J20*M$30 -> 0.112 | N20: =$J20*N$30 -> 0.116 | O20: =$J20*O$30 -> 0.124 | P20: =$J20*P$30 -> 0.132 | Q20: =$J20*Q$30 -> 0.14 | R20: =$J20*R$30 -> 0.148 | ... AD20: =$J20*AD$30 -> 0.532
A21: 战力 | B21: 攻击加持 | C21: 1 | D21: =F21/I21 -> 0.1 | E21: =D21 -> 0.1 | F21: =C21*H21 -> 10 | G21: =F21*2 -> 20 | H21: 10 | I21: 100 | J21: =F21 -> 10 | K21: =$J21*K$30 -> 10.4 | L21: =$J21*L$30 -> 10.8 | M21: =$J21*M$30 -> 11.2 | N21: =$J21*N$30 -> 11.6 | O21: =$J21*O$30 -> 12.4 | P21: =$J21*P$30 -> 13.2 | Q21: =$J21*Q$30 -> 14 | R21: =$J21*R$30 -> 14.8 | ... AD21: =$J21*AD$30 -> 53.2
A22: 战力 | B22: 对敌人伤害 | C22: 1 | D22: =F22/I22 -> 0.001 | E22: =D22 -> 0.001 | F22: =C22*H22 -> 0.1 | G22: =F22*6 -> 0.6 | H22: 0.1 | I22: 100 | J22: =F22 -> 0.1 | K22: =$J22*K$30 -> 0.104 | L22: =$J22*L$30 -> 0.108 | M22: =$J22*M$30 -> 0.112 | N22: =$J22*N$30 -> 0.116 | O22: =$J22*O$30 -> 0.124 | P22: =$J22*P$30 -> 0.132 | Q22: =$J22*Q$30 -> 0.14 | R22: =$J22*R$30 -> 0.148 | ... AD22: =$J22*AD$30 -> 0.532
A23: PVP属性 | B23: 刚毅/韧性 | C23: 1 | D23: =F23/I23 -> 1 | E23: =D23 -> 1 | F23: =C23*H23 -> 100 | H23: 100 | I23: 100 | J23: =F23 -> 100 | K23: =$J23*K$30 -> 104 | L23: =$J23*L$30 -> 108 | M23: =$J23*M$30 -> 112 | N23: =$J23*N$30 -> 116 | O23: =$J23*O$30 -> 124 | P23: =$J23*P$30 -> 132 | Q23: =$J23*Q$30 -> 140 | R23: =$J23*R$30 -> 148 | ... AD23: =$J23*AD$30 -> 532
A24: PVP属性 | B24: 稳固率+ | C24: 1 | D24: =F24/I24 -> 0.001 | E24: =D24 -> 0.001 | F24: =C24*H24 -> 0.1 | H24: 0.1 | I24: 100 | J24: =F24 -> 0.1 | K24: =$J24*K$30 -> 0.104 | L24: =$J24*L$30 -> 0.108 | M24: =$J24*M$30 -> 0.112 | N24: =$J24*N$30 -> 0.116 | O24: =$J24*O$30 -> 0.124 | P24: =$J24*P$30 -> 0.132 | Q24: =$J24*Q$30 -> 0.14 | R24: =$J24*R$30 -> 0.148 | ... AD24: =$J24*AD$30 -> 0.532
A25: PVP属性 | B25: 格挡率+ | C25: 1 | D25: =F25/I25 -> 0.001 | E25: =D25 -> 0.001 | F25: =C25*H25 -> 0.1 | H25: 0.1 | I25: 100 | J25: =F25 -> 0.1 | K25: =$J25*K$30 -> 0.104 | L25: =$J25*L$30 -> 0.108 | M25: =$J25*M$30 -> 0.112 | N25: =$J25*N$30 -> 0.116 | O25: =$J25*O$30 -> 0.124 | P25: =$J25*P$30 -> 0.132 | Q25: =$J25*Q$30 -> 0.14 | R25: =$J25*R$30 -> 0.148 | ... AD25: =$J25*AD$30 -> 0.532
A26: PVP属性 | B26: 抵抗率+ | C26: 1 | D26: =F26/I26 -> 0.001 | E26: =D26 -> 0.001 | F26: =C26*H26 -> 0.1 | H26: 0.1 | I26: 100 | J26: =F26 -> 0.1 | K26: =$J26*K$30 -> 0.104 | L26: =$J26*L$30 -> 0.108 | M26: =$J26*M$30 -> 0.112 | N26: =$J26*N$30 -> 0.116 | O26: =$J26*O$30 -> 0.124 | P26: =$J26*P$30 -> 0.132 | Q26: =$J26*Q$30 -> 0.14 | R26: =$J26*R$30 -> 0.148 | ... AD26: =$J26*AD$30 -> 0.532
A27: PVP属性 | B27: 精准/穿透 | C27: 1 | D27: =F27/I27 -> 0.001 | E27: =D27 -> 0.001 | F27: =C27*H27 -> 0.1 | H27: 0.1 | I27: 100 | J27: =F27 -> 0.1 | K27: =$J27*K$30 -> 0.104 | L27: =$J27*L$30 -> 0.108 | M27: =$J27*M$30 -> 0.112 | N27: =$J27*N$30 -> 0.116 | O27: =$J27*O$30 -> 0.124 | P27: =$J27*P$30 -> 0.132 | Q27: =$J27*Q$30 -> 0.14 | R27: =$J27*R$30 -> 0.148 | ... AD27: =$J27*AD$30 -> 0.532
A28: PVP属性 | B28: 破防/破法 | C28: 1 | D28: =F28/I28 -> 0.001 | E28: =D28 -> 0.001 | F28: =C28*H28 -> 0.1 | H28: 0.1 | I28: 100 | J28: =F28 -> 0.1 | K28: =$J28*K$30 -> 0.104 | L28: =$J28*L$30 -> 0.108 | M28: =$J28*M$30 -> 0.112 | N28: =$J28*N$30 -> 0.116 | O28: =$J28*O$30 -> 0.124 | P28: =$J28*P$30 -> 0.132 | Q28: =$J28*Q$30 -> 0.14 | R28: =$J28*R$30 -> 0.148 | ... AD28: =$J28*AD$30 -> 0.532
A29: 基础 | B29: 防御加持 | C29: 1 | D29: =F29/I29 -> #DIV/0! | E29: =D29 -> #DIV/0! | F29: =C29*H29 -> #DIV/0! | H29: =J44 -> #DIV/0! | I29: 100 | J29: =F29 -> #DIV/0! | K29: =$J29*K$30 -> #DIV/0! | L29: =$J29*L$30 -> #DIV/0! | M29: =$J29*M$30 -> #DIV/0! | N29: =$J29*N$30 -> #DIV/0! | O29: =$J29*O$30 -> #DIV/0! | P29: =$J29*P$30 -> #DIV/0! | Q29: =$J29*Q$30 -> #DIV/0! | R29: =$J29*R$30 -> #DIV/0! | ... AD29: =$J29*AD$30 -> #DIV/0!
K30: 1.04 | L30: 1.08 | M30: 1.12 | N30: 1.16 | O30: 1.24 | P30: 1.32 | Q30: 1.4 | R30: 1.48 | S30: 1.72 | T30: 1.96 | U30: 2.2 | V30: 2.68 | W30: 3.16 | X30: 3.64 | Y30: 4.12 | Z30: 4.36 | AA30: 4.6 | AB30: 4.84 | AC30: 5.08 | AD30: 5.32
K31: =K30-1 -> 0.04 | L31: =L30-1 -> 0.08 | M31: =M30-1 -> 0.12 | N31: =N30-1 -> 0.16 | O31: =O30-1 -> 0.24 | P31: =P30-1 -> 0.32 | Q31: =Q30-1 -> 0.4 | R31: =R30-1 -> 0.48 | ... AD31: =AD30-1 -> 4.32
K32: 1.12 | L32: =L30-K30 -> 0.04 | M32: =M30-L30 -> 0.04 | N32: =N30-M30 -> 0.04 | O32: =O30-N30 -> 0.08 | P32: =P30-O30 -> 0.08 | Q32: =Q30-P30 -> 0.08 | R32: =R30-Q30 -> 0.08 | S32: =S30-R30 -> 0.24 | ... AD32: =AD30-AC30 -> 0.24
K33: 0.04 | L33: 0.08 | M33: 0.12 | N33: 0.16 | O33: 0.24 | P33: 0.32 | Q33: 0.4 | R33: 0.48 | S33: 0.72 | T33: 0.96 | U33: 1.2 | V33: 1.68 | W33: 2.16 | X33: 2.64 | Y33: 3.12 | Z33: 3.36 | AA33: 3.6 | AB33: 3.84 | AC33: 4.08 | AD33: 4.32
L34: =K34^$K36+0.01 -> 0.01
B35: 属性类型 | C35: 当前最大 | D35: 0.5 | E35: 单件投放 | F35: 基础属性投放 | G35: 熔炼属性投放 | H35: 套装属性投放 | I35: 0强化最大值 | J35: 增长系数 | K35: 分散件数值 | L35: 公式用，勿动 | P35: 9
A36: 基础 | B36: 生命值 | C36: 20000 | D36: =C36*$D$35 -> 10000 | E36: =(D36-H36)/K36 -> 2000 | I36: =G36/$AD$30 -> 0 | J36: =I36/$C$14 -> 0 | K36: =COUNTIF(装备属性池!$C$3:$K$11,装备属性池!$L36) -> 5 | L36: 生命值 | M36: 1 | P36: 4
A37: 基础 | B37: 法力值 | C37: 16000 | D37: =C37*$D$35 -> 8000 | E37: =(D37-H37)/K37 -> 2666.6667 | I37: =G37/$AD$30 -> 0 | J37: =I37/$C$14 -> 0 | K37: =COUNTIF(装备属性池!$C$3:$K$11,装备属性池!$L37) -> 3 | L37: 法力值 | M37: 1
A38: 基础 | B38: 物理防御 | C38: 4000 | D38: =C38*$D$35 -> 2000 | E38: =D38/K38 -> 400 | I38: =G38/$AD$30 -> 0 | J38: =I38/$C$14 -> 0 | K38: =COUNTIF(装备属性池!$C$3:$K$11,装备属性池!$L38) -> 5 | L38: 物理防御 | M38: 1
A39: 基础 | B39: 法术防御 | C39: 4000 | D39: =C39*$D$35 -> 2000 | E39: =D39/K39 -> 666.66667 | I39: =G39/$AD$30 -> 0 | J39: =I39/$C$14 -> 0 | K39: =COUNTIF(装备属性池!$C$3:$K$11,装备属性池!$L39) -> 3 | L39: 法术防御 | M39: 1
A40: 基础 | B40: 火属性抗性 | C40: 30 | D40: 150 | E40: =D40/K40 -> #DIV/0! | I40: =G40/$AD$30 -> 0 | J40: =I40/$C$14 -> 0 | K40: =COUNTIF(装备属性池!$C$3:$K$11,装备属性池!$L40) -> 0 | L40: 火属性抗性
A41: 基础 | B41: 水属性抗性 | C41: 30 | D41: 150 | E41: =D41/K41 -> #DIV/0! | I41: =G41/$AD$30 -> 0 | J41: =I41/$C$14 -> 0 | K41: =COUNTIF(装备属性池!$C$3:$K$11,装备属性池!$L41) -> 0 | L41: 水属性抗性 | P41: 黄巾套
...

Sheet 无双吕布
C2: 武器 | D2: 项链 | E2: 戒指 | F2: 手镯 | G2: 头盔 | H2: 衣服 | I2: 腰带 | J2: 裤子 | K2: 鞋子 | M2: 套装： | N2: 1 | O2: 2 | P2: 3 | Q2: 4 | R2: 5 | S2: 6 | T2: 7 | U2: 8 | V2: 9
A3: 战力属性 | C3: 熔炼属性 | D3: 熔炼属性 | E3: 熔炼属性 | F3: 熔炼属性 | G3: 熔炼属性 | H3: 熔炼属性 | I3: 熔炼属性 | J3: 熔炼属性 | K3: 熔炼属性 | P3: 生命值 | R3: 防御加持 | T3: 攻击加持 | V3: 物理/法术攻击
A4: PVP属性 | B4: 1 | C4: 物理、法术攻击 | D4: 物理、法术攻击 | E4: 物理、法术攻击 | F4: 物理、法术攻击 | G4: 物理、法术攻击 | H4: 物理、法术攻击 | I4: 物理、法术攻击 | J4: 物理、法术攻击 | K4: 物理、法术攻击 | R4: 黄巾起义 套装 | V4: 1
A5: 基础属性 | B5: 2 | C5: 致命伤害 | D5: 致命伤害 | E5: 致命伤害 | F5: 致命伤害 | G5: 水属性伤害 | H5: 火属性伤害 | I5: 对目标伤害 | J5: 光属性伤害 | K5: 暗属性伤害 | M5: 1 | N5: 武器 第三条 | O5: 从攻击加持 改成 伤害增加 | R5: 1 | S5: 激活熔炼强化属性效果
A6: 防御属性 | B6: 3 | C6: 对目标伤害 | D6: 武力/智力 | E6: 武力/智力 | F6: 武力/智力 | G6: 攻击加持 | H6: 攻击加持 | I6: 攻击加持 | J6: 攻击加持 | K6: 攻击加持 | M6: 2 | N6: 手镯 | O6: 伤害增加 改成 改成致命伤害 | Q6: 0.15 | R6: 2 | S6: 防御力 | T6: 1000
B7: 4 | C7: 破防/破法 | D7: 破防/破法 | E7: 精准/穿透 | F7: 精准/穿透 | G7: 格挡 | H7: 刚毅 | I7: 抵抗 | J7: 韧性 | K7: 稳固 | M7: 3 | N7: 全部攻击力至 | O7: 最大值提升 | P7: 500 | R7: 3 | S7: 防御加持 | T7: 100
C8: 基础属性 | D8: 基础属性 | E8: 基础属性 | F8: 基础属性 | G8: 基础属性 | H8: 基础属性 | I8: 基础属性 | J8: 基础属性 | K8: 基础属性 | M8: 4 | N8: 武力智力 | O8: 最大值 | P8: 200 | R8: 4 | S8: 物理致命 | T8: 0.1
B9: 1 | C9: 物理、法术攻击 | D9: 法力值 | E9: 法力值 | F9: 法力值 | G9: 生命值 | H9: 生命值 | I9: 生命值 | J9: 生命值 | K9: 生命值 | M9: 5 | N9: 加持类型 | O9: 改成万分比 | P9: 数值从10-1000 | Q9: 0.1-10 | R9: 5 | S9: 法术致命 | T9: 0.1
B10: 2 | C10: 物理致命 | D10: 法术防御 | E10: 法术防御 | F10: 法术防御 | G10: 物理防御 | H10: 物理防御 | I10: 物理防御 | J10: 物理防御 | K10: 物理防御 | M10: 6 | N10: 5件防具第3条都改成 攻击加持 | P10: 上限改成10 | R10: 6 | S10: 移动速度 | T10: 0.1
B11: 3 | C11: 法术致命 | D11: 意志 | E11: 意志 | F11: 意志 | G11: 意志 | H11: 体力 | I11: 体力 | J11: 体力 | K11: 体力 | M11: 7 | N11: 8件增加黄巾套装效果 右侧数值（特殊效果程序实现：激活熔炼强化属性效果） | R11: 7 | S11: 攻击速度 | T11: 0.1
F12: 随机值过低 每一项保证随机区间量是100 | M12: 8 | N12: 最大值橙色
A13: 类型 | B13: 属性类型 | C13: 装备等级 | D13: 增长值 | E13: 最低值 | F13: 最高值 | G13: 模拟器 | H13: 增长系数 | I13: 随机量 | J13: 极值 | K13: 强化1 | L13: 强化2 | M13: 强化3 | N13: 强化4 | O13: 强化5 | P13: 强化6 | Q13: 强化7 | R13: 强化8 | S13: 强化9 | T13: 强化10 | U13: 强化11 | V13: 强化12 | W13: 强化13 | X13: 强化14 | Y13: 强化15 | Z13: 强化16 | AA13: 强化17 | AB13: 强化18 | AC13: 强化19 | AD13: 强化20
A14: 战力 | B14: 物理/法术攻击 | C14: 1 | D14: =F14/I14 -> 7 | E14: =D14 -> 7 | F14: =(H14*C14) -> 700 | G14: =F14*9 -> 6300 | H14: 700 | I14: 100 | J14: =F14 -> 700 | K14: =$J14*K$30 -> 728 | L14: =$J14*L$30 -> 756 | M14: =$J14*M$30 -> 784 | N14: =$J14*N$30 -> 812 | O14: =$J14*O$30 -> 868 | P14: =$J14*P$30 -> 924 | Q14: =$J14*Q$30 -> 980 | R14: =$J14*R$30 -> 1036 | ... AD14: =$J14*AD$30 -> 3724
A15: 战力 | B15: 武力/智力 | C15: 1 | D15: =F15/I15 -> 2.5 | E15: =D15 -> 2.5 | F15: =(H15*C15) -> 250 | G15: =F15*5 -> 1250 | H15: 250 | I15: 100 | J15: =F15 -> 250 | K15: =$J15*K$30 -> 260 | L15: =$J15*L$30 -> 270 | M15: =$J15*M$30 -> 280 | N15: =$J15*N$30 -> 290 | O15: =$J15*O$30 -> 310 | P15: =$J15*P$30 -> 330 | Q15: =$J15*Q$30 -> 350 | R15: =$J15*R$30 -> 370 | ... AD15: =$J15*AD$30 -> 1330
A16: 战力 | B16: 致命伤害+ | C16: 1 | D16: =F16/I16 -> 0.0015 | E16: =D16 -> 0.0015 | F16: =C16*H16 -> 0.15 | G16: =F16*3 -> 0.45 | H16: 0.15 | I16: 100 | J16: =F16 -> 0.15 | K16: =$J16*K$30 -> 0.156 | L16: =$J16*L$30 -> 0.162 | M16: =$J16*M$30 -> 0.168 | N16: =$J16*N$30 -> 0.174 | O16: =$J16*O$30 -> 0.186 | P16: =$J16*P$30 -> 0.198 | Q16: =$J16*Q$30 -> 0.21 | R16: =$J16*R$30 -> 0.222 | ... AD16: =$J16*AD$30 -> 0.798
A17: 战力 | B17: 光属性伤害+ | C17: 1 | D17: =F17/I17 -> 0.0015 | E17: =D17 -> 0.0015 | F17: =C17*H17 -> 0.15 | H17: 0.15 | I17: 100 | J17: =F17 -> 0.15 | K17: =$J17*K$30 -> 0.156 | L17: =$J17*L$30 -> 0.162 | M17: =$J17*M$30 -> 0.168 | N17: =$J17*N$30 -> 0.174 | O17: =$J17*O$30 -> 0.186 | P17: =$J17*P$30 -> 0.198 | Q17: =$J17*Q$30 -> 0.21 | R17: =$J17*R$30 -> 0.222 | ... AD17: =$J17*AD$30 -> 0.798
A18: 战力 | B18: 暗属性伤害+ | C18: 1 | D18: =F18/I18 -> 0.0015 | E18: =D18 -> 0.0015 | F18: =C18*H18 -> 0.15 | H18: 0.15 | I18: 100 | J18: =F18 -> 0.15 | K18: =$J18*K$30 -> 0.156 | L18: =$J18*L$30 -> 0.162 | M18: =$J18*M$30 -> 0.168 | N18: =$J18*N$30 -> 0.174 | O18: =$J18*O$30 -> 0.186 | P18: =$J18*P$30 -> 0.198 | Q18: =$J18*Q$30 -> 0.21 | R18: =$J18*R$30 -> 0.222 | ... AD18: =$J18*AD$30 -> 0.798
A19: 战力 | B19: 火属性伤害+ | C19: 1 | D19: =F19/I19 -> 0.0015 | E19: =D19 -> 0.0015 | F19: =C19*H19 -> 0.15 | H19: 0.15 | I19: 100 | J19: =F19 -> 0.15 | K19: =$J19*K$30 -> 0.156 | L19: =$J19*L$30 -> 0.162 | M19: =$J19*M$30 -> 0.168 | N19: =$J19*N$30 -> 0.174 | O19: =$J19*O$30 -> 0.186 | P19: =$J19*P$30 -> 0.198 | Q19: =$J19*Q$30 -> 0.21 | R19: =$J19*R$30 -> 0.222 | ... AD19: =$J19*AD$30 -> 0.798
A20: 战力 | B20: 水属性伤害+ | C20: 1 | D20: =F20/I20 -> 0.0015 | E20: =D20 -> 0.0015 | F20: =C20*H20 -> 0.15 | H20: 0.15 | I20: 100 | J20: =F20 -> 0.15 | K20: =$J20*K$30 -> 0.156 | L20: =$J20*L$30 -> 0.162 | M20: =$J20*M$30 -> 0.168 | N20: =$J20*N$30 -> 0.174 | O20: =$J20*O$30 -> 0.186 | P20: =$J20*P$30 -> 0.198 | Q20: =$J20*Q$30 -> 0.21 | R20: =$J20*R$30 -> 0.222 | ... AD20: =$J20*AD$30 -> 0.798
A21: 战力 | B21: 攻击加持 | C21: 1 | D21: =F21/I21 -> 0.15 | E21: =D21 -> 0.15 | F21: =C21*H21 -> 15 | G21: =F21*2 -> 30 | H21: 15 | I21: 100 | J21: =F21 -> 15 | K21: =$J21*K$30 -> 15.6 | L21: =$J21*L$30 -> 16.2 | M21: =$J21*M$30 -> 16.8 | N21: =$J21*N$30 -> 17.4 | O21: =$J21*O$30 -> 18.6 | P21: =$J21*P$30 -> 19.8 | Q21: =$J21*Q$30 -> 21 | R21: =$J21*R$30 -> 22.2 | ... AD21: =$J21*AD$30 -> 79.8
A22: 战力 | B22: 对敌人伤害 | C22: 1 | D22: =F22/I22 -> 0.001 | E22: =D22 -> 0.001 | F22: =C22*H22 -> 0.1 | G22: =F22*6 -> 0.6 | H22: 0.1 | I22: 100 | J22: =F22 -> 0.1 | K22: =$J22*K$30 -> 0.104 | L22: =$J22*L$30 -> 0.108 | M22: =$J22*M$30 -> 0.112 | N22: =$J22*N$30 -> 0.116 | O22: =$J22*O$30 -> 0.124 | P22: =$J22*P$30 -> 0.132 | Q22: =$J22*Q$30 -> 0.14 | R22: =$J22*R$30 -> 0.148 | ... AD22: =$J22*AD$30 -> 0.532
A23: PVP属性 | B23: 刚毅/韧性 | C23: 1 | D23: =F23/I23 -> 1.2 | E23: =D23 -> 1.2 | F23: =C23*H23 -> 120 | H23: 120 | I23: 100 | J23: =F23 -> 120 | K23: =$J23*K$30 -> 124.8 | L23: =$J23*L$30 -> 129.6 | M23: =$J23*M$30 -> 134.4 | N23: =$J23*N$30 -> 139.2 | O23: =$J23*O$30 -> 148.8 | P23: =$J23*P$30 -> 158.4 | Q23: =$J23*Q$30 -> 168 | R23: =$J23*R$30 -> 177.6 | ... AD23: =$J23*AD$30 -> 638.4
A24: PVP属性 | B24: 稳固率+ | C24: 1 | D24: =F24/I24 -> 0.0012 | E24: =D24 -> 0.0012 | F24: =C24*H24 -> 0.12 | H24: 0.12 | I24: 100 | J24: =F24 -> 0.12 | K24: =$J24*K$30 -> 0.1248 | L24: =$J24*L$30 -> 0.1296 | M24: =$J24*M$30 -> 0.1344 | N24: =$J24*N$30 -> 0.1392 | O24: =$J24*O$30 -> 0.1488 | P24: =$J24*P$30 -> 0.1584 | Q24: =$J24*Q$30 -> 0.168 | R24: =$J24*R$30 -> 0.1776 | ... AD24: =$J24*AD$30 -> 0.6384
A25: PVP属性 | B25: 格挡率+ | C25: 1 | D25: =F25/I25 -> 0.0012 | E25: =D25 -> 0.0012 | F25: =C25*H25 -> 0.12 | H25: 0.12 | I25: 100 | J25: =F25 -> 0.12 | K25: =$J25*K$30 -> 0.1248 | L25: =$J25*L$30 -> 0.1296 | M25: =$J25*M$30 -> 0.1344 | N25: =$J25*N$30 -> 0.1392 | O25: =$J25*O$30 -> 0.1488 | P25: =$J25*P$30 -> 0.1584 | Q25: =$J25*Q$30 -> 0.168 | R25: =$J25*R$30 -> 0.1776 | ... AD25: =$J25*AD$30 -> 0.6384
A26: PVP属性 | B26: 抵抗率+ | C26: 1 | D26: =F26/I26 -> 0.0012 | E26: =D26 -> 0.0012 | F26: =C26*H26 -> 0.12 | H26: 0.12 | I26: 100 | J26: =F26 -> 0.12 | K26: =$J26*K$30 -> 0.1248 | L26: =$J26*L$30 -> 0.1296 | M26: =$J26*M$30 -> 0.1344 | N26: =$J26*N$30 -> 0.1392 | O26: =$J26*O$30 -> 0.1488 | P26: =$J26*P$30 -> 0.1584 | Q26: =$J26*Q$30 -> 0.168 | R26: =$J26*R$30 -> 0.1776 | ... AD26: =$J26*AD$30 -> 0.6384
A27: PVP属性 | B27: 精准/穿透 | C27: 1 | D27: =F27/I27 -> 0.0012 | E27: =D27 -> 0.0012 | F27: =C27*H27 -> 0.12 | H27: 0.12 | I27: 100 | J27: =F27 -> 0.12 | K27: =$J27*K$30 -> 0.1248 | L27: =$J27*L$30 -> 0.1296 | M27: =$J27*M$30 -> 0.1344 | N27: =$J27*N$30 -> 0.1392 | O27: =$J27*O$30 -> 0.1488 | P27: =$J27*P$30 -> 0.1584 | Q27: =$J27*Q$30 -> 0.168 | R27: =$J27*R$30 -> 0.1776 | ... AD27: =$J27*AD$30 -> 0.6384
A28: PVP属性 | B28: 破防/破法 | C28: 1 | D28: =F28/I28 -> 0.0012 | E28: =D28 -> 0.0012 | F28: =C28*H28 -> 0.12 | H28: 0.12 | I28: 100 | J28: =F28 -> 0.12 | K28: =$J28*K$30 -> 0.1248 | L28: =$J28*L$30 -> 0.1296 | M28: =$J28*M$30 -> 0.1344 | N28: =$J28*N$30 -> 0.1392 | O28: =$J28*O$30 -> 0.1488 | P28: =$J28*P$30 -> 0.1584 | Q28: =$J28*Q$30 -> 0.168 | R28: =$J28*R$30 -> 0.1776 | ... AD28: =$J28*AD$30 -> 0.6384
A29: 基础 | B29: 防御加持 | C29: 1 | D29: =F29/I29 -> #DIV/0! | E29: =D29 -> #DIV/0! | F29: =C29*H29 -> #DIV/0! | H29: =J44 -> #DIV/0! | I29: 100 | J29: =F29 -> #DIV/0! | K29: =$J29*K$30 -> #DIV/0! | L29: =$J29*L$30 -> #DIV/0! | M29: =$J29*M$30 -> #DIV/0! | N29: =$J29*N$30 -> #DIV/0! | O29: =$J29*O$30 -> #DIV/0! | P29: =$J29*P$30 -> #DIV/0! | Q29: =$J29*Q$30 -> #DIV/0! | R29: =$J29*R$30 -> #DIV/0! | ... AD29: =$J29*AD$30 -> #DIV/0!
K30: 1.04 | L30: 1.08 | M30: 1.12 | N30: 1.16 | O30: 1.24 | P30: 1.32 | Q30: 1.4 | R30: 1.48 | S30: 1.72 | T30: 1.96 | U30: 2.2 | V30: 2.68 | W30: 3.16 | X30: 3.64 | Y30: 4.12 | Z30: 4.36 | AA30: 4.6 | AB30: 4.84 | AC30: 5.08 | AD30: 5.32
K31: =K30-1 -> 0.04 | L31: =L30-1 -> 0.08 | M31: =M30-1 -> 0.12 | N31: =N30-1 -> 0.16 | O31: =O30-1 -> 0.24 | P31: =P30-1 -> 0.32 | Q31: =Q30-1 -> 0.4 | R31: =R30-1 -> 0.48 | ... AD31: =AD30-1 -> 4.32
K32: 1.12 | L32: =L30-K30 -> 0.04 | M32: =M30-L30 -> 0.04 | N32: =N30-M30 -> 0.04 | O32: =O30-N30 -> 0.08 | P32: =P30-O30 -> 0.08 | Q32: =Q30-P30 -> 0.08 | R32: =R30-Q30 -> 0.08 | S32: =S30-R30 -> 0.24 | ... AD32: =AD30-AC30 -> 0.24
K33: 0.04 | L33: 0.08 | M33: 0.12 | N33: 0.16 | O33: 0.24 | P33: 0.32 | Q33: 0.4 | R33: 0.48 | S33: 0.72 | T33: 0.96 | U33: 1.2 | V33: 1.68 | W33: 2.16 | X33: 2.64 | Y33: 3.12 | Z33: 3.36 | AA33: 3.6 | AB33: 3.84 | AC33: 4.08 | AD33: 4.32
L34: =K34^$K36+0.01 -> 0.01
B35: 属性类型 | C35: 当前最大 | D35: 0.5 | E35: 单件投放 | F35: 基础属性投放 | G35: 熔炼属性投放 | H35: 套装属性投放 | I35: 0强化最大值 | J35: 增长系数 | K35: 分散件数值 | L35: 公式用，勿动 | P35: 9
A36: 基础 | B36: 生命值 | C36: 20000 | D36: =C36*$D$35 -> 10000 | E36: =(D36-H36)/K36 -> 2000 | I36: =G36/$AD$30 -> 0 | J36: =I36/$C$14 -> 0 | K36: =COUNTIF(无双吕布!$C$3:$K$11,无双吕布!$L36) -> 5 | L36: 生命值 | M36: 1 | P36: 4
A37: 基础 | B37: 法力值 | C37: 16000 | D37: =C37*$D$35 -> 8000 | E37: =(D37-H37)/K37 -> 2666.6667 | I37: =G37/$AD$30 -> 0 | J37: =I37/$C$14 -> 0 | K37: =COUNTIF(无双吕布!$C$3:$K$11,无双吕布!$L37) -> 3 | L37: 法力值 | M37: 1
A38: 基础 | B38: 物理防御 | C38: 4000 | D38: =C38*$D$35 -> 2000 | E38: =D38/K38 -> 400 | I38: =G38/$AD$30 -> 0 | J38: =I38/$C$14 -> 0 | K38: =COUNTIF(无双吕布!$C$3:$K$11,无双吕布!$L38) -> 5 | L38: 物理防御 | M38: 1
A39: 基础 | B39: 法术防御 | C39: 4000 | D39: =C39*$D$35 -> 2000 | E39: =D39/K39 -> 666.66667 | I39: =G39/$AD$30 -> 0 | J39: =I39/$C$14 -> 0 | K39: =COUNTIF(无双吕布!$C$3:$K$11,无双吕布!$L39) -> 3 | L39: 法术防御 | M39: 1
A40: 基础 | B40: 火属性抗性 | C40: 30 | D40: 150 | E40: =D40/K40 -> #DIV/0! | I40: =G40/$AD$30 -> 0 | J40: =I40/$C$14 -> 0 | K40: =COUNTIF(无双吕布!$C$3:$K$11,无双吕布!$L40) -> 0 | L40: 火属性抗性
A41: 基础 | B41: 水属性抗性 | C41: 30 | D41: 150 | E41: =D41/K41 -> #DIV/0! | I41: =G41/$AD$30 -> 0 | J41: =I41/$C$14 -> 0 | K41: =COUNTIF(无双吕布!$C$3:$K$11,无双吕布!$L41) -> 0 | L41: 水属性抗性 | P41: 黄巾套
...

Sheet 强化等级显示
A1: 强化等级 | B1: 强化加成
A2: 1 | B2: 0.04 | C2: 4
A3: 2 | B3: 0.08 | C3: 4
A4: 3 | B4: 0.12 | C4: 4
A5: 4 | B5: 0.16 | C5: 4
A6: 5 | B6: 0.24 | C6: 8
A7: 6 | B7: 0.32 | C7: 8
A8: 7 | B8: 0.4 | C8: 8
A9: 8 | B9: 0.48 | C9: 8
A10: 9 | B10: 0.72 | C10: 24
A11: 10 | B11: 0.96 | C11: 24
A12: 11 | B12: 1.2 | C12: 24
A13: 12 | B13: 1.68 | C13: 48
... A21: 20 | B21: 4.32 | C21: 24

Sheet 最大值参考
A1: 属性 | B1: 头盔 | C1: 衣服 | D1: 腰带 | E1: 裤子 | F1: 鞋子 | G1: 手镯 | H1: 项链 | I1: 戒指 | J1: 武器 | K1: 套装效果 | L1: 总和 | M1: 头盔 | N1: 衣服 | O1: 腰带 | P1: 裤子 | Q1: 鞋子 | R1: 手镯 | S1: 项链 | T1: 戒指 | U1: 武器 | V1: 总和 | W1: 乘算结果 | X1: 百分比收益
A2: 生命值 | B2: =800+1143+200+600 -> 2743 | C2: =800+2328+112 -> 3240 | D2: =800+1143+600 -> 2543 | E2: =800+1143+153 -> 2096 | F2: =800+1143+600+200 -> 2743 | G2: =750+571 -> 1321 | H2: =552 -> 552 | I2: =571 -> 571 | J2: =1164 -> 1164 | K2: =1600 -> 1600 | L2: =SUM(B2:K2) -> 18573 | N2: 0.015 | P2: 0.03 | V2: =SUM(M2:U2) -> 0.045 | W2: =L2*(1+V2) -> 19408.785 | X2: =W2-L2 -> 835.785
A3: 法力值 | B3: =800+1143 -> 1943 | C3: =800+2328 -> 3128 | D3: =800+1143 -> 1943 | E3: =800+1143 -> 1943 | F3: =580+800+1143 -> 2523 | G3: =571 -> 571 | H3: =552 -> 552 | I3: =571 -> 571 | J3: =1164 -> 1164 | K3: =1600 -> 1600 | L3: =SUM(B3:K3) -> 15938 | V3: =SUM(M3:U3) -> 0 | W3: =L3*(1+V3) -> 15938 | X3: =W3-L3 -> 0
A4: 物理防御 | B4: =478 -> 478 | C4: =717 -> 717 | D4: =251 -> 251 | E4: =598 -> 598 | F4: 239 | L4: =SUM(B4:K4) -> 2283 | V4: =SUM(M4:U4) -> 0 | W4: =L4*(1+V4) -> 2283 | X4: =W4-L4 -> 0
A5: 法术防御 | E5: =520 -> 520 | G5: =1062 -> 1062 | H5: =1062 -> 1062 | I5: =679 -> 679 | L5: =SUM(B5:K5) -> 3323 | N5: 0.04 | V5: =SUM(M5:U5) -> 0.04 | W5: =L5*(1+V5) -> 3455.92 | X5: =W5-L5 -> 132.92
A6: 火属性抗性 | L6: =SUM(B6:K6) -> 0 | V6: =SUM(M6:U6) -> 0 | W6: =L6*(1+V6) -> 0 | X6: =W6-L6 -> 0
A7: 水属性抗性 | L7: =SUM(B7:K7) -> 0 | V7: =SUM(M7:U7) -> 0 | W7: =L7*(1+V7) -> 0 | X7: =W7-L7 -> 0
A8: 光属性抗性 | B8: 11 | L8: =SUM(B8:K8) -> 11 | V8: =SUM(M8:U8) -> 0 | W8: =L8*(1+V8) -> 11 | X8: =W8-L8 -> 0
A9: 暗属性抗性 | L9: =SUM(B9:K9) -> 0 | V9: =SUM(M9:U9) -> 0 | W9: =L9*(1+V9) -> 0 | X9: =W9-L9 -> 0
A10: 防御加持 | B10: =39 -> 39 | C10: =11+39 -> 50 | D10: =16+33 -> 49 | E10: =33 -> 33 | F10: =16+39 -> 55 | G10: =16 -> 16 | H10: =10 -> 10 | J10: =12 -> 12 | K10: =20+10 -> 30 | L10: =SUM(B10:K10) -> 294 | V10: =SUM(M10:U10) -> 0 | W10: =L10*(1+V10) -> 294 | X10: =W10-L10 -> 0
A11: 体力 | D11: =99 -> 99 | F11: =140 -> 140 | G11: =175 -> 175 | H11: =211 -> 211 | I11: =57+175 -> 232 | L11: =SUM(B11:K11) -> 857 | O11: =2% -> 0.02 | Q11: 0.04 | V11: =SUM(M11:U11) -> 0.06 | W11: =L11*(1+V11) -> 908.42 | X11: =W11-L11 -> 51.42
A12: 意志 | B12: =44 -> 44 | F12: =54 -> 54 | G12: =175 -> 175 | H12: =95+211 -> 306 | I12: =175 -> 175 | L12: =SUM(B12:K12) -> 754 | M12: =2% -> 0.02 | Q12: 0.03 | V12: =SUM(M12:U12) -> 0.05 | W12: =L12*(1+V12) -> 791.7 | X12: =W12-L12 -> 37.7
A13: 物理致命 | C13: =10% -> 0.1 | D13: =12% -> 0.12 | E13: =12% -> 0.12 | J13: =5% -> 0.05 | L13: =SUM(B13:K13) -> 0.39 | V13: =SUM(M13:U13) -> 0 | W13: =L13*(1+V13) -> 0.39 | X13: =W13-L13 -> 0
A14: 法术致命 | J14: =5% -> 0.05 | L14: =SUM(B14:K14) -> 0.05 | V14: =SUM(M14:U14) -> 0 | W14: =L14*(1+V14) -> 0.05 | X14: =W14-L14 -> 0
A15: 光属性抵抗 | H15: =10% -> 0.1 | L15: =SUM(B15:K15) -> 0.1 | V15: =SUM(M15:U15) -> 0 | W15: =L15*(1+V15) -> 0.1 | X15: =W15-L15 -> 0
A16: 暗属性抵抗 | H16: =10% -> 0.1 | L16: =SUM(B16:K16) -> 0.1 | V16: =SUM(M16:U16) -> 0 | W16: =L16*(1+V16) -> 0.1 | X16: =W16-L16 -> 0
A17: 火属性抵抗 | H17: =10% -> 0.1 | L17: =SUM(B17:K17) -> 0.1 | V17: =SUM(M17:U17) -> 0 | W17: =L17*(1+V17) -> 0.1 | X17: =W17-L17 -> 0 | Z17: 武器强化印记
A18: 水属性抵抗 | H18: =10% -> 0.1 | L18: =SUM(B18:K18) -> 0.1 | V18: =SUM(M18:U18) -> 0 | W18: =L18*(1+V18) -> 0.1 | X18: =W18-L18 -> 0 | Z18: 武器攻击力提升
A19: 物理攻击 | B19: =176+35+40 -> 251 | D19: =40+35 -> 75 | F19: =35 -> 35 | G19: =120+50+60+300 -> 530 | H19: =200+50+60+800 -> 1110 | I19: =50+60+300 -> 410 | J19: =1682+30+602+363+195 -> 2872 | L19: =SUM(B19:K19) -> 5283 | N19: =5% -> 0.05 | O19: 0.06 | P19: 0.05 | S19: =15%+5% -> 0.2 | T19: =5%+5% -> 0.1 | U19: =15%+3%+10.6%+19% -> 0.476 | V19: =SUM(M19:U19) -> 0.936 | W19: =L19*(AB19)+(L19*Z19) -> 29267.41 | X19: =W19-L19 -> 23984.41 | Z19: =312% -> 3.12 | AB19: =1.05*1.06*1.05*1.15*1.05*1.1*1.15*1.03*1.106*1.19 -> 2.4199224 | AC19: =L19*(1+Z19)*AB19 -> 52671.934
A20: 法术攻击 | B20: =35 -> 35 | D20: =35 -> 35 | F20: =35 -> 35 | G20: =120+60+300 -> 480 | H20: =200+60+800 -> 1060 | I20: =60+300 -> 360 | J20: =1282+602+363+195 -> 2442 | L20: =SUM(B20:K20) -> 4447 | O20: 0.06 | S20: =15% -> 0.15 | T20: =5%+5% -> 0.1 | U20: =15%+3%+19% -> 0.37 | V20: =SUM(M20:U20) -> 0.68 | W20: =L20*(AB20) -> 8169.2858 | X20: =W20-L20 -> 3722.2858 | Z20: =312% -> 3.12 | AB20: =1.06*1.15*1.1*1.37 -> 1.837033
A21: 武力 | B21: =150+103+81+195+45 -> 574 | C21: =150+130+60+50+60 -> 450 | D21: =138+95+77+40+228+45 -> 623 | E21: =150+103+40+50+60 -> 403 | F21: =147+95+75+237+45 -> 599 | G21: =76+120+175+80 -> 451 | H21: =76+211+80 -> 367 | I21: =45+164+175+80 -> 464 | J21: =70+50+40 -> 160 | L21: =SUM(B21:K21) -> 4091 | O21: =5% -> 0.05 | V21: =SUM(M21:U21) -> 0.05 | W21: =L21*(1+V21) -> 4295.55 | X21: =W21-L21 -> 204.55
A22: 智力 | B22: =103+81+195+45 -> 424 | C22: =130+60+50+60 -> 300 | D22: =95+77+40+228+45 -> 485 | E22: =103+40+50+60 -> 253 | F22: =95+75+237+45 -> 452 | G22: =76+120+175+80 -> 451 | H22: =76+211+80 -> 367 | I22: =164+175+80 -> 419 | J22: =70+50 -> 120 | L22: =SUM(B22:K22) -> 3271 | O22: =5% -> 0.05 | V22: =SUM(M22:U22) -> 0.05 | W22: =L22*(1+V22) -> 3434.55 | X22: =W22-L22 -> 163.55
A23: 致命伤害 | C23: =11.1%+7% -> 0.181 | E23: =4%+7% -> 0.11 | G23: =12.1% -> 0.121 | H23: =20%+12.1%+6.5%+6% -> 0.446 | I23: =12.6%+6.5%+5%+5% -> 0.291 | J23: =20%+3.9% -> 0.239 | K23: =30% -> 0.3 | L23: =SUM(B23:K23) -> 1.688 | V23: =SUM(M23:U23) -> 0 | W23: =L23*(1+V23) -> 1.688 | X23: =W23-L23 -> 0
A24: 光属性伤害 | G24: =7% -> 0.07 | H24: =4% -> 0.04 | L24: =SUM(B24:K24) -> 0.11 | V24: =SUM(M24:U24) -> 0 | W24: =L24*(1+V24) -> 0.11 | X24: =W24-L24 -> 0 | Z24: =J19*(1.15*1.03*1.106*1.19)*Z19 -> 13969.349
A25: 暗属性伤害 | G25: =6% -> 0.06 | L25: =SUM(B25:K25) -> 0.06 | V25: =SUM(M25:U25) -> 0 | W25: =L25*(1+V25) -> 0.06 | X25: =W25-L25 -> 0
A26: 火属性伤害 | H26: =9% -> 0.09 | I26: =2% -> 0.02 | L26: =SUM(B26:K26) -> 0.11 | V26: =SUM(M26:U26) -> 0 | W26: =L26*(1+V26) -> 0.11 | X26: =W26-L26 -> 0
A27: 水属性伤害 | G27: =4%+4% -> 0.08 | I27: =10% -> 0.1 | L27: =SUM(B27:K27) -> 0.18 | V27: =SUM(M27:U27) -> 0 | W27: =L27*(1+V27) -> 0.18 | X27: =W27-L27 -> 0
A28: 刚毅 | D28: =105 -> 105 | G28: =105 -> 105 | L28: =SUM(B28:K28) -> 210 | V28: =SUM(M28:U28) -> 0 | W28: =L28*(1+V28) -> 210 | X28: =W28-L28 -> 0
A29: 韧性 | F29: =105 -> 105 | I29: =105 -> 105 | L29: =SUM(B29:K29) -> 210 | V29: =SUM(M29:U29) -> 0 | W29: =L29*(1+V29) -> 210 | X29: =W29-L29 -> 0
A30: 稳固率 | B30: =5%+0.7% -> 0.057 | D30: =1% -> 0.01 | E30: =5% -> 0.05 | F30: =2.1%+15% -> 0.171 | L30: =SUM(B30:K30) -> 0.288 | V30: =SUM(M30:U30) -> 0 | W30: =L30*(1+V30) -> 0.288 | X30: =W30-L30 -> 0
A31: 格挡率 | B31: =8%+2% -> 0.1 | C31: =3.7% -> 0.037 | D31: =2%+8% -> 0.1 | E31: =4.3%+8% -> 0.123 | F31: =8%+2% -> 0.1 | I31: =4% -> 0.04 | L31: =SUM(B31:K31) -> 0.5 | V31: =SUM(M31:U31) -> 0 | W31: =L31*(1+V31) -> 0.5 | X31: =W31-L31 -> 0
A32: 抵抗率 | C32: =0.4% -> 0.004 | E32: =2.9% -> 0.029 | L32: =SUM(B32:K32) -> 0.033 | V32: =SUM(M32:U32) -> 0 | W32: =L32*(1+V32) -> 0.033 | X32: =W32-L32 -> 0
A33: 精准率 | B33: =3.6%+15% -> 0.186 | D33: =0.3%+5% -> 0.053 | F33: =2.1% -> 0.021 | G33: =8%+9% -> 0.17 | H33: =5%+8%+2% -> 0.15 | I33: =8% -> 0.08 | J33: =5% -> 0.05 | L33: =SUM(B33:K33) -> 0.71 | V33: =SUM(M33:U33) -> 0 | W33: =L33*(1+V33) -> 0.71 | X33: =W33-L33 -> 0
A34: 穿透率 | B34: =1.2% -> 0.012 | D34: =0.7% -> 0.007 | F34: =2.1% -> 0.021 | G34: =9% -> 0.09 | H34: =5%+2% -> 0.07 | J34: =3% -> 0.03 | L34: =SUM(B34:K34) -> 0.23 | V34: =SUM(M34:U34) -> 0 | W34: =L34*(1+V34) -> 0.23 | X34: =W34-L34 -> 0
A35: 破防 | B35: 0.06 | D35: =15% -> 0.15 | E35: =5% -> 0.05 | G35: =5%+2.7% -> 0.077 | H35: =2.2% -> 0.022 | I35: =0.1% -> 0.001 | J35: =8% -> 0.08 | L35: =SUM(B35:K35) -> 0.44 | V35: =SUM(M35:U35) -> 0 | W35: =L35*(1+V35) -> 0.44 | X35: =W35-L35 -> 0
A36: 破法 | G36: =5%+1.5% -> 0.065 | I36: 0.025 | J36: =9% -> 0.09 | L36: =SUM(B36:K36) -> 0.18 | V36: =SUM(M36:U36) -> 0 | W36: =L36*(1+V36) -> 0.18 | X36: =W36-L36 -> 0
A37: 攻击加持 | B37: =20 -> 20 | C37: =16+20 -> 36 | D37: =15+16 -> 31 | E37: =16 -> 16 | F37: =15+20 -> 35 | G37: =16+5 -> 21 | H37: =10 -> 10 | J37: =35+12 -> 47 | K37: =20+5 -> 25 | L37: =SUM(B37:K37) -> 241 | V37: =SUM(M37:U37) -> 0 | W37: =L37*(1+V37) -> 241 | X37: =W37-L37 -> 0
A38: 对敌人伤害增加 | B38: 0.18 | C38: =6% -> 0.06 | F38: 0.05 | G38: =2.6% -> 0.026 | H38: =2.6%+8% -> 0.106 | I38: =1.3% -> 0.013 | J38: 0.15 | L38: =SUM(B38:K38) -> 0.585 | V38: =SUM(M38:U38) -> 0 | W38: =L38*(1+V38) -> 0.585 | X38: =W38-L38 -> 0
W129: 0.001
W130: =W129*100 -> 0.1

Sheet 词条掉落属性参考
B1: 方案A | C1: 先判断是通用/职业，如果是职业再判断是4/16，再判断详细职业 | K1: 通用/4职业/16职业分池，掉落时先随机池，再随属性
B2: 原始概率
B3: 词条 | C3: 一次掉落 | D3: 二次掉落 | E3: 可用概率 | F3: 不可用概率 | K3: 词条 | L3: 一次掉落 | M3: 可用概率 | N3: 不可用概率
B4: 通用 | C4: 0.05 | D4: - | E4: =C4 -> 0.05 | K4: 通用 | L4: 0.07 | M4: =L4 -> 0.07
B5: 四职业 | C5: =1-C4 -> 0.95 | D5: 0.2 | E5: =(C5*D5)/4 -> 0.0475 | F5: =(C5*D5)/4*3 -> 0.1425 | K5: 四职业 | L5: 0.28 | M5: =(L5)/4 -> 0.07 | N5: =(L5)/4*3 -> 0.21
B6: 十六职业 | C6: - | D6: =1-D5 -> 0.8 | E6: =(C5*D6)/16 -> 0.0475 | F6: =(C5*D6)/16*15 -> 0.7125 | K6: 十六职业 | L6: =1-L4-L5 -> 0.65 | M6: =(L6)/16 -> 0.040625 | N6: =(L6)/16*15 -> 0.609375
E8: =SUM(E4:E6) -> 0.145 | F8: =SUM(F4:F6) -> 0.855 | M8: =SUM(M4:M6) -> 0.180625 | N8: =SUM(N5:N6) -> 0.819375
B10: 偏新手概率
B11: 词条 | C11: 一次掉落 | D11: 二次掉落 | E11: 可用概率 | F11: 不可用概率
B12: 通用 | C12: 0.3 | D12: - | E12: =C12 -> 0.3
B13: 四职业 | C13: =1-C12 -> 0.7 | D13: 0.3 | E13: =(C13*D13)/4 -> 0.0525 | F13: =(C13*D13)/4*3 -> 0.1575
B14: 十六职业 | C14: - | D14: =1-D13 -> 0.7 | E14: =(C13*D14)/16 -> 0.030625 | F14: =(C13*D14)/16*15 -> 0.459375
B18: 偏后期概率
B19: 词条 | C19: 一次掉落 | D19: 二次掉落 | E19: 可用概率 | F19: 不可用概率
B20: 通用 | C20: 0.01 | D20: - | E20: =C20 -> 0.01
B21: 四职业 | C21: =1-C20 -> 0.99 | D21: 0.03 | E21: =(C21*D21)/4 -> 0.007425 | F21: =(C21*D21)/4*3 -> 0.022275
B22: 十六职业 | C22: - | D22: =1-D21 -> 0.97 | E22: =(C21*D22)/16 -> 0.06001875 | F22: =(C21*D22)/16*15 -> 0.90028125

Sheet 属性池
A2: 部位 | B2: 属性类型 | C2: 装备等级 | D2: 增长值 | E2: 最低值 | F2: 最高值 | G2: 模拟器 | H2: 增长系数 | I2: 随机量 | J2: 极值 | K2: 强化1 | L2: 强化2 | M2: 强化3 | N2: 强化4 | O2: 强化5 | P2: 强化6 | Q2: 强化7 | R2: 强化8 | S2: 强化9 | T2: 强化10 | U2: 强化11 | V2: 强化12 | W2: 强化13 | X2: 强化14 | Y2: 强化15 | Z2: 强化16 | AA2: 强化17 | AB2: 强化18 | AC2: 强化19 | AD2: 强化20
A3: 武器 | B3: 攻击力 | C3: 53 | D3: =F3/I3 -> 10.6 | E3: =D3 -> 10.6 | F3: =C3*H3 -> 1060 | H3: 20 | I3: 100 | J3: =F3 -> 1060 | K3: =$J3*K$18 -> 1070.6 | L3: =$J3*L$18 -> 1083.226 | M3: =$J3*M$18 -> 1098.2961 | N3: =$J3*N$18 -> 1116.3272 | O3: =$J3*O$18 -> 1137.9631 | P3: =$J3*P$18 -> 1164.0118 | Q3: =$J3*Q$18 -> 1195.4986 | R3: =$J3*R$18 -> 1233.7375 | ... AD3: =$J3*AD$18 -> 4612.877
A4: 武器 | B4: 致命伤害 | C4: 50 | D4: =F4/I4 -> 0.01 | E4: =D4 -> 0.01 | F4: =C4*H4 -> 1 | H4: 0.02 | I4: 100 | J4: =F4 -> 1 | K4: =$J4*K$18 -> 1.01 | L4: =$J4*L$18 -> 1.0219113 | M4: =$J4*M$18 -> 1.0361284 | N4: =$J4*N$18 -> 1.0531389 | O4: =$J4*O$18 -> 1.0735501 | P4: =$J4*P$18 -> 1.0981244 | Q4: =$J4*Q$18 -> 1.1278289 | R4: =$J4*R$18 -> 1.1639033 | ... AD4: =$J4*AD$18 -> 4.3517708
A5: 武器 | B5: 破双防 | C5: 50 | D5: =F5/I5 -> 0.001 | E5: =D5 -> 0.001 | F5: =C5*H5 -> 0.1 | H5: 0.002 | I5: 100 | J5: =F5 -> 0.1 | K5: =$J5*K$18 -> 0.101 | L5: =$J5*L$18 -> 0.10219113 | M5: =$J5*M$18 -> 0.10361284 | N5: =$J5*N$18 -> 0.10531389 | O5: =$J5*O$18 -> 0.10735501 | P5: =$J5*P$18 -> 0.10981244 | Q5: =$J5*Q$18 -> 0.11278289 | R5: =$J5*R$18 -> 0.11639033 | ... AD5: =$J5*AD$18 -> 0.43517708
A6: 武器 | B6: 对敌人伤害增加 | C6: 50 | D6: =F6/I6 -> 0.001 | E6: =D6 -> 0.001 | F6: =C6*H6 -> 0.1 | H6: 0.002 | I6: 100 | J6: =F6 -> 0.1 | K6: =$J6*K$18 -> 0.101 | L6: =$J6*L$18 -> 0.10219113 | M6: =$J6*M$18 -> 0.10361284 | N6: =$J6*N$18 -> 0.10531389 | O6: =$J6*O$18 -> 0.10735501 | P6: =$J6*P$18 -> 0.10981244 | Q6: =$J6*Q$18 -> 0.11278289 | R6: =$J6*R$18 -> 0.11639033 | ... AD6: =$J6*AD$18 -> 0.43517708
